Workbook

Sheet ЗАГАЛЬНА ТАБЛИЦЯ
A1: ОПЛАТА за надані допоміжні послуги з регулювання частоти та активної потужності (РПЧ)
A2: станом на 30.04.2026 року
A3: 2 0 2 5 р і к
A5: ПОКАЗНИКИ | B5: ТОВ "ЗНАМЕНСЬКА БЕСС" | C5: ТОВ "ОЛЕКСАНДРІЙСЬКА БЕСС" | D5: ВСЬОГО: | E5: ВСЬОГО ПІДСУМКОМ:
B6: 10,32180 МВт*год | C6: 15,33776 МВт*год
A7: НЕК "УКРЕНЕРГО"
A8: 2025 рік
A9: СІЧЕНЬ 2025
A10: дРПЧ_с, МВт | B10: =ЗНАМЕНКА!B8 -> 0 | C10: =ОЛЕКСАНДРІЯ!B8 -> 0 | D10: =SUM(B10:C10) -> 0 | E10: =+D10 -> 0
A11: Нараховано, Гривень | B11: =ЗНАМЕНКА!D8 -> 0 | C11: =ОЛЕКСАНДРІЯ!D8 -> 0 | D11: =SUM(B11:C11) -> 0 | E11: =+D11 -> 0
A12: Виплачено, Гривень | B12: =ЗНАМЕНКА!E8 -> 0 | C12: =ОЛЕКСАНДРІЯ!E8 -> 0 | D12: =SUM(B12:C12) -> 0 | E12: =+D12 -> 0
A13: Заборгованість, Гривень | B13: =ЗНАМЕНКА!F8 -> 0 | C13: =ОЛЕКСАНДРІЯ!F8 -> 0 | D13: =SUM(B13:C13) -> 0 | E13: =D13 -> 0
A14: %% виплат | B14: =IF(ISERROR(B12/B11),"",B12/B11) | C14: =IF(ISERROR(C12/C11),"",C12/C11) | D14: =IF(ISERROR(D12/D11),"",D12/D11) | E14: =IF(ISERROR(E12/E11),"",E12/E11)
A15: ЛЮТИЙ 2025
A16: дРПЧ_с, МВт | B16: =ЗНАМЕНКА!B9 -> 0 | C16: =ОЛЕКСАНДРІЯ!B9 -> 0 | D16: =SUM(B16:C16) -> 0 | E16: =E10+D16 -> 0
A17: Нараховано, Гривень | B17: =ЗНАМЕНКА!D9 -> 0 | C17: =ОЛЕКСАНДРІЯ!D9 -> 0 | D17: =SUM(B17:C17) -> 0 | E17: =E11+D17 -> 0
A18: Виплачено, Гривень | B18: =ЗНАМЕНКА!E9 -> 0 | C18: =ОЛЕКСАНДРІЯ!E9 -> 0 | D18: =SUM(B18:C18) -> 0 | E18: =E12+D18 -> 0
A19: Заборгованість, Гривень | B19: =ЗНАМЕНКА!F9 -> 0 | C19: =ОЛЕКСАНДРІЯ!F9 -> 0 | D19: =SUM(B19:C19) -> 0 | E19: =E13+D19 -> 0
A20: %% виплат | B20: =IF(ISERROR(B18/B17),"",B18/B17) | C20: =IF(ISERROR(C18/C17),"",C18/C17) | D20: =IF(ISERROR(D18/D17),"",D18/D17) | E20: =IF(ISERROR(E18/E17),"",E18/E17)
A21: БЕРЕЗЕНЬ 2025
A22: дРПЧ_с, МВт | B22: =ЗНАМЕНКА!B10 -> 0 | C22: =ОЛЕКСАНДРІЯ!B10 -> 0 | D22: =SUM(B22:C22) -> 0 | E22: =E16+D22 -> 0
A23: Нараховано, Гривень | B23: =ЗНАМЕНКА!D10 -> 0 | C23: =ОЛЕКСАНДРІЯ!D10 -> 0 | D23: =SUM(B23:C23) -> 0 | E23: =E17+D23 -> 0
A24: Виплачено, Гривень | B24: =ЗНАМЕНКА!E10 -> 0 | C24: =ОЛЕКСАНДРІЯ!E10 -> 0 | D24: =SUM(B24:C24) -> 0 | E24: =E18+D24 -> 0
A25: Заборгованість, Гривень | B25: =ЗНАМЕНКА!F10 -> 0 | C25: =ОЛЕКСАНДРІЯ!F10 -> 0 | D25: =SUM(B25:C25) -> 0 | E25: =E19+D25 -> 0
A26: %% виплат | B26: =IF(ISERROR(B24/B23),"",B24/B23) | C26: =IF(ISERROR(C24/C23),"",C24/C23) | D26: =IF(ISERROR(D24/D23),"",D24/D23) | E26: =IF(ISERROR(E24/E23),"",E24/E23)
A27: КВІТЕНЬ 2025
A28: дРПЧ_с, МВт | B28: =ЗНАМЕНКА!B11 -> 0 | C28: =ОЛЕКСАНДРІЯ!B11 -> 0 | D28: =SUM(B28:C28) -> 0 | E28: =E22+D28 -> 0
A29: Нараховано, Гривень | B29: =ЗНАМЕНКА!D11 -> 0 | C29: =ОЛЕКСАНДРІЯ!D11 -> 0 | D29: =SUM(B29:C29) -> 0 | E29: =E23+D29 -> 0
A30: Виплачено, Гривень | B30: =ЗНАМЕНКА!E11 -> 0 | C30: =ОЛЕКСАНДРІЯ!E11 -> 0 | D30: =SUM(B30:C30) -> 0 | E30: =E24+D30 -> 0
A31: Заборгованість, Гривень | B31: =ЗНАМЕНКА!F11 -> 0 | C31: =ОЛЕКСАНДРІЯ!F11 -> 0 | D31: =SUM(B31:C31) -> 0 | E31: =E25+D31 -> 0
A32: %% виплат | B32: =IF(ISERROR(B30/B29),"",B30/B29) | C32: =IF(ISERROR(C30/C29),"",C30/C29) | D32: =IF(ISERROR(D30/D29),"",D30/D29) | E32: =IF(ISERROR(E30/E29),"",E30/E29)
A33: ТРАВЕНЬ 2025
A34: дРПЧ_с, МВт | B34: =ЗНАМЕНКА!B12 -> 0 | C34: =ОЛЕКСАНДРІЯ!B12 -> 0 | D34: =SUM(B34:C34) -> 0 | E34: =E28+D34 -> 0
A35: Нараховано, Гривень | B35: =ЗНАМЕНКА!D12 -> 0 | C35: =ОЛЕКСАНДРІЯ!D12 -> 0 | D35: =SUM(B35:C35) -> 0 | E35: =E29+D35 -> 0
A36: Виплачено, Гривень | B36: =ЗНАМЕНКА!E12 -> 0 | C36: =ОЛЕКСАНДРІЯ!E12 -> 0 | D36: =SUM(B36:C36) -> 0 | E36: =E30+D36 -> 0
A37: Заборгованість, Гривень | B37: =ЗНАМЕНКА!F12 -> 0 | C37: =ОЛЕКСАНДРІЯ!F12 -> 0 | D37: =SUM(B37:C37) -> 0 | E37: =E31+D37 -> 0
A38: %% виплат | B38: =IF(ISERROR(B36/B35),"",B36/B35) | C38: =IF(ISERROR(C36/C35),"",C36/C35) | D38: =IF(ISERROR(D36/D35),"",D36/D35) | E38: =IF(ISERROR(E36/E35),"",E36/E35)
A39: ЧЕРВЕНЬ 2025
A40: дРПЧ_с, МВт | B40: =ЗНАМЕНКА!B13 -> 0 | C40: =ОЛЕКСАНДРІЯ!B13 -> 0 | D40: =SUM(B40:C40) -> 0 | E40: =E34+D40 -> 0
A41: Нараховано, Гривень | B41: =ЗНАМЕНКА!D13 -> 0 | C41: =ОЛЕКСАНДРІЯ!D13 -> 0 | D41: =SUM(B41:C41) -> 0 | E41: =E35+D41 -> 0
...

Sheet ЗНАМЕНКА
A1: ОПЛАТА за надані допоміжні послуги з регулювання частоти та активної потужності (РПЧ)
A2: ТОВ "ЗНАМЕНСЬКА БЕСС" - 8 МВт
G3: ='ЗАГАЛЬНА ТАБЛИЦЯ'!A2 -> станом на 30.04.2026 року
A5: ПОКУПЕЦЬ | B5: ОБСЯГ ПОСЛУГ, МВт | C5: ЦІНА (середньозважена) за період, грн | D5: НАРАХОВАНО, грн. | E5: ВИПЛАЧЕНО, грн. | F5: ЗАБОРГОВАНІСТЬ, грн. | G5: %% виплат | J5: ДАТА ОПЛАТИ | K5: За який місяць | L5: Сума оплати, грн.
A6: НЕК "УКРЕНЕРГО"
A7: 2025 рік
A8: січень 2025 | D8: =ROUND(ROUND(B8*C8,2)*1.2,2) -> 0 | F8: =D8-E8 -> 0 | G8: =IF(ISERROR(E8/D8*100%),"",E8/D8*100%)
A9: лютий 2025 | D9: =ROUND(ROUND(B9*C9,2)*1.2,2) -> 0 | F9: =D9-E9 -> 0 | G9: =IF(ISERROR(E9/D9*100%),"",E9/D9*100%)
A10: березень 2025 | D10: =ROUND(ROUND(B10*C10,2)*1.2,2) -> 0 | F10: =D10-E10 -> 0 | G10: =IF(ISERROR(E10/D10*100%),"",E10/D10*100%)
A11: квітень 2025 | D11: =ROUND(ROUND(B11*C11,2)*1.2,2) -> 0 | F11: =D11-E11 -> 0 | G11: =IF(ISERROR(E11/D11*100%),"",E11/D11*100%)
A12: травень 2025 | D12: =ROUND(ROUND(B12*C12,2)*1.2,2) -> 0 | F12: =D12-E12 -> 0 | G12: =IF(ISERROR(E12/D12*100%),"",E12/D12*100%)
A13: червень 2025 | D13: =ROUND(ROUND(B13*C13,2)*1.2,2) -> 0 | F13: =D13-E13 -> 0 | G13: =IF(ISERROR(E13/D13*100%),"",E13/D13*100%)
A14: липень 2025 | D14: =ROUND(ROUND(B14*C14,2)*1.2,2) -> 0 | F14: =D14-E14 -> 0 | G14: =IF(ISERROR(E14/D14*100%),"",E14/D14*100%)
A15: серпень 2025 | D15: =ROUND(ROUND(B15*C15,2)*1.2,2) -> 0 | F15: =D15-E15 -> 0 | G15: =IF(ISERROR(E15/D15*100%),"",E15/D15*100%)
A16: вересень 2025 | B16: 192 | C16: 300 | D16: =ROUND(ROUND(B16*C16,2)*1.2,2) -> 69120 | E16: 69120 | F16: =D16-E16 -> 0 | G16: =IF(ISERROR(E16/D16*100%),"",E16/D16*100%) -> 1 | J16: 45967 | K16: 09 | L16: 69120
A17: жовтень 2025 | B17: 5960 | C17: 746.89 | D17: =ROUND(ROUND(B17*C17,2)*1.2,2) -> 5341757.3 | E17: 5341757.3 | F17: =D17-E17 -> 0 | G17: =IF(ISERROR(E17/D17*100%),"",E17/D17*100%) -> 1 | J17: 46010 | K17: 10 | L17: 5341757.3
A18: листопад 2025 | B18: 5760 | C18: 750.04 | D18: =ROUND(ROUND(B18*C18,2)*1.2,2) -> 5184276.5 | E18: 5184276.5 | F18: =D18-E18 -> 0 | G18: =IF(ISERROR(E18/D18*100%),"",E18/D18*100%) -> 1 | J18: 46022 | K18: 11 | L18: 5184276.5
A19: грудень 2025 | B19: 5952 | C19: 761.62 | D19: =ROUND(ROUND(B19*C19,2)*1.2,2) -> 5439794.7 | E19: 5439794.7 | F19: =D19-E19 -> 0 | G19: =IF(ISERROR(E19/D19*100%),"",E19/D19*100%) -> 1 | J19: 45677 | K19: 12 | L19: 5439794.7
A20: ВСЬОГО за 2025 рік: | B20: =SUM(B8:B19) -> 17864 | D20: =SUM(D8:D19) -> 16034948 | E20: =SUM(E8:E19) -> 16034948 | F20: =SUM(F8:F19) -> 0 | G20: =IF(ISERROR(E20/D20*100%),"",E20/D20*100%) -> 1 | L20: =SUM(L16:L19) -> 16034948
A22: ПОКУПЕЦЬ | B22: ОБСЯГ ПОСЛУГ, МВт | C22: ЦІНА (середньозважена) за період, грн | D22: НАРАХОВАНО, грн. | E22: ВИПЛАЧЕНО, грн. | F22: ЗАБОРГОВАНІСТЬ, грн. | G22: %% виплат | J22: ДАТА ОПЛАТИ | K22: За який місяць | L22: Сума оплати, грн.
A23: НЕК "УКРЕНЕРГО"
A24: 2026 рік
A25: січень 2026 | B25: 5944 | C25: 775.89 | D25: =ROUND(ROUND(B25*C25,2)*1.2,2) -> 5534268.2 | E25: 5534268.2 | F25: =D25-E25 -> 0 | G25: =IF(ISERROR(E25/D25*100%),"",E25/D25*100%) -> 1 | J25: 46072 | K25: 01 | L25: 5534268.2
A26: лютий 2026 | B26: 5376 | C26: 786.34 | D26: =ROUND(ROUND(B26*C26,2)*1.2,2) -> 5072836.6 | E26: 5072836.6 | F26: =D26-E26 -> 0 | G26: =IF(ISERROR(E26/D26*100%),"",E26/D26*100%) -> 1 | J26: 46101 | K26: 02 | L26: 5072836.6
A27: березень 2026 | B27: 5944 | C27: 781.73 | D27: =ROUND(ROUND(B27*C27,2)*1.2,2) -> 5575923.7 | E27: 5575923.7 | F27: =D27-E27 -> 0 | G27: =IF(ISERROR(E27/D27*100%),"",E27/D27*100%) -> 1 | J27: 46133 | K27: 03 | L27: 5575923.7
A28: квітень 2026 | B28: 5760 | C28: 787.43 | D28: =ROUND(ROUND(B28*C28,2)*1.2,2) -> 5442716.2 | E28: 0 | F28: =D28-E28 -> 5442716.2 | G28: =IF(ISERROR(E28/D28*100%),"",E28/D28*100%) -> 0
A29: травень 2026 | D29: =ROUND(ROUND(B29*C29,2)*1.2,2) -> 0 | F29: =D29-E29 -> 0 | G29: =IF(ISERROR(E29/D29*100%),"",E29/D29*100%)
A30: червень 2026 | D30: =ROUND(ROUND(B30*C30,2)*1.2,2) -> 0 | F30: =D30-E30 -> 0 | G30: =IF(ISERROR(E30/D30*100%),"",E30/D30*100%)
A31: липень 2026 | D31: =ROUND(ROUND(B31*C31,2)*1.2,2) -> 0 | F31: =D31-E31 -> 0 | G31: =IF(ISERROR(E31/D31*100%),"",E31/D31*100%)
A32: серпень 2026 | D32: =ROUND(ROUND(B32*C32,2)*1.2,2) -> 0 | F32: =D32-E32 -> 0 | G32: =IF(ISERROR(E32/D32*100%),"",E32/D32*100%)
A33: вересень 2026 | D33: =ROUND(ROUND(B33*C33,2)*1.2,2) -> 0 | F33: =D33-E33 -> 0 | G33: =IF(ISERROR(E33/D33*100%),"",E33/D33*100%)
A34: жовтень 2026 | D34: =ROUND(ROUND(B34*C34,2)*1.2,2) -> 0 | F34: =D34-E34 -> 0 | G34: =IF(ISERROR(E34/D34*100%),"",E34/D34*100%)
A35: листопад 2026 | D35: =ROUND(ROUND(B35*C35,2)*1.2,2) -> 0 | F35: =D35-E35 -> 0 | G35: =IF(ISERROR(E35/D35*100%),"",E35/D35*100%)
A36: грудень 2026 | D36: =ROUND(ROUND(B36*C36,2)*1.2,2) -> 0 | F36: =D36-E36 -> 0 | G36: =IF(ISERROR(E36/D36*100%),"",E36/D36*100%)
A37: ВСЬОГО за 2026 рік: | B37: =SUM(B25:B36) -> 23024 | D37: =SUM(D25:D36) -> 21625745 | E37: =SUM(E25:E36) -> 16183029 | F37: =SUM(F25:F36) -> 5442716.2 | G37: =IF(ISERROR(E37/D37*100%),"",E37/D37*100%) -> 0.74832237 | L37: =SUM(L25:L36) -> 16183029

Sheet ОЛЕКСАНДРІЯ
A1: ОПЛАТА за надані допоміжні послуги з регулювання частоти та активної потужності (РПЧ)
A2: ТОВ "ОЛЕКСАНДРІЙСЬКА БЕСС" - 10 МВт
G3: ='ЗАГАЛЬНА ТАБЛИЦЯ'!A2 -> станом на 30.04.2026 року
A5: ПОКУПЕЦЬ | B5: ОБСЯГ ПОСЛУГ, МВт | C5: ЦІНА (середньозважена) за період, грн | D5: НАРАХОВАНО, грн. | E5: ВИПЛАЧЕНО, грн. | F5: ЗАБОРГОВАНІСТЬ, грн. | G5: %% виплат | J5: ДАТА ОПЛАТИ | K5: За який місяць | L5: Сума оплати, грн.
A6: НЕК "УКРЕНЕРГО"
A7: 2025 рік
A8: січень 2025 | D8: =ROUND(ROUND(B8*C8,2)*1.2,2) -> 0 | F8: =D8-E8 -> 0 | G8: =IF(ISERROR(E8/D8*100%),"",E8/D8*100%)
A9: лютий 2025 | D9: =ROUND(ROUND(B9*C9,2)*1.2,2) -> 0 | F9: =D9-E9 -> 0 | G9: =IF(ISERROR(E9/D9*100%),"",E9/D9*100%)
A10: березень 2025 | D10: =ROUND(ROUND(B10*C10,2)*1.2,2) -> 0 | F10: =D10-E10 -> 0 | G10: =IF(ISERROR(E10/D10*100%),"",E10/D10*100%)
A11: квітень 2025 | D11: =ROUND(ROUND(B11*C11,2)*1.2,2) -> 0 | F11: =D11-E11 -> 0 | G11: =IF(ISERROR(E11/D11*100%),"",E11/D11*100%)
A12: травень 2025 | D12: =ROUND(ROUND(B12*C12,2)*1.2,2) -> 0 | F12: =D12-E12 -> 0 | G12: =IF(ISERROR(E12/D12*100%),"",E12/D12*100%)
A13: червень 2025 | D13: =ROUND(ROUND(B13*C13,2)*1.2,2) -> 0 | F13: =D13-E13 -> 0 | G13: =IF(ISERROR(E13/D13*100%),"",E13/D13*100%)
A14: липень 2025 | D14: =ROUND(ROUND(B14*C14,2)*1.2,2) -> 0 | F14: =D14-E14 -> 0 | G14: =IF(ISERROR(E14/D14*100%),"",E14/D14*100%)
A15: серпень 2025 | D15: =ROUND(ROUND(B15*C15,2)*1.2,2) -> 0 | F15: =D15-E15 -> 0 | G15: =IF(ISERROR(E15/D15*100%),"",E15/D15*100%)
A16: вересень 2025 | B16: 0 | C16: 0 | D16: =ROUND(ROUND(B16*C16,2)*1.2,2) -> 0 | E16: 0 | F16: =D16-E16 -> 0 | G16: =IF(ISERROR(E16/D16*100%),"",E16/D16*100%) | J16: 46016 | K16: 10 | L16: 6056755.2
A17: жовтень 2025 | B17: 7440 | C17: 678.4 | D17: =ROUND(ROUND(B17*C17,2)*1.2,2) -> 6056755.2 | E17: 6056755.2 | F17: =D17-E17 -> 0 | G17: =IF(ISERROR(E17/D17*100%),"",E17/D17*100%) -> 1 | J17: 46022 | K17: 11 | L17: 5886172.8
A18: листопад 2025 | B18: 7200 | C18: 681.27 | D18: =ROUND(ROUND(B18*C18,2)*1.2,2) -> 5886172.8 | E18: 5886172.8 | F18: =D18-E18 -> 0 | G18: =IF(ISERROR(E18/D18*100%),"",E18/D18*100%) -> 1 | J18: 45677 | K18: 12 | L18: 6176301.1
A19: грудень 2025 | B19: 7440 | C19: 691.79 | D19: =ROUND(ROUND(B19*C19,2)*1.2,2) -> 6176301.1 | E19: 6176301.1 | F19: =D19-E19 -> 0 | G19: =IF(ISERROR(E19/D19*100%),"",E19/D19*100%) -> 1
A20: ВСЬОГО за 2025 рік: | B20: =SUM(B8:B19) -> 22080 | D20: =SUM(D8:D19) -> 18119229 | E20: =SUM(E8:E19) -> 18119229 | F20: =SUM(F8:F19) -> 0 | G20: =IF(ISERROR(E20/D20*100%),"",E20/D20*100%) -> 1 | L20: =SUM(L16:L19) -> 18119229
A22: ПОКУПЕЦЬ | B22: ОБСЯГ ПОСЛУГ, МВт | C22: ЦІНА (середньозважена) за період, грн | D22: НАРАХОВАНО, грн. | E22: ВИПЛАЧЕНО, грн. | F22: ЗАБОРГОВАНІСТЬ, грн. | G22: %% виплат | J22: ДАТА ОПЛАТИ | K22: За який місяць | L22: Сума оплати, грн.
A23: НЕК "УКРЕНЕРГО"
A24: 2026 рік
A25: січень 2026 | B25: 7440 | C25: 704.75 | D25: =ROUND(ROUND(B25*C25,2)*1.2,2) -> 6292008 | E25: 6292008 | F25: =D25-E25 -> 0 | G25: =IF(ISERROR(E25/D25*100%),"",E25/D25*100%) -> 1 | J25: 46072 | K25: 01 | L25: 6292008
A26: лютий 2026 | B26: 6720 | C26: 714.24 | D26: =ROUND(ROUND(B26*C26,2)*1.2,2) -> 5759631.4 | E26: 5759631.4 | F26: =D26-E26 -> 0 | G26: =IF(ISERROR(E26/D26*100%),"",E26/D26*100%) -> 1 | J26: 46101 | K26: 02 | L26: 5759631.4
A27: березень 2026 | B27: 7430 | C27: 710.05 | D27: =ROUND(ROUND(B27*C27,2)*1.2,2) -> 6330805.8 | E27: 6330805.8 | F27: =D27-E27 -> 0 | G27: =IF(ISERROR(E27/D27*100%),"",E27/D27*100%) -> 1 | J27: 46133 | K27: 03 | L27: 6330805.8
A28: квітень 2026 | B28: 7180 | C28: 715.23 | D28: =ROUND(ROUND(B28*C28,2)*1.2,2) -> 6162421.7 | E28: 0 | F28: =D28-E28 -> 6162421.7 | G28: =IF(ISERROR(E28/D28*100%),"",E28/D28*100%) -> 0
A29: травень 2026 | D29: =ROUND(ROUND(B29*C29,2)*1.2,2) -> 0 | F29: =D29-E29 -> 0 | G29: =IF(ISERROR(E29/D29*100%),"",E29/D29*100%)
A30: червень 2026 | D30: =ROUND(ROUND(B30*C30,2)*1.2,2) -> 0 | F30: =D30-E30 -> 0 | G30: =IF(ISERROR(E30/D30*100%),"",E30/D30*100%)
A31: липень 2026 | D31: =ROUND(ROUND(B31*C31,2)*1.2,2) -> 0 | F31: =D31-E31 -> 0 | G31: =IF(ISERROR(E31/D31*100%),"",E31/D31*100%)
A32: серпень 2026 | D32: =ROUND(ROUND(B32*C32,2)*1.2,2) -> 0 | F32: =D32-E32 -> 0 | G32: =IF(ISERROR(E32/D32*100%),"",E32/D32*100%)
A33: вересень 2026 | D33: =ROUND(ROUND(B33*C33,2)*1.2,2) -> 0 | F33: =D33-E33 -> 0 | G33: =IF(ISERROR(E33/D33*100%),"",E33/D33*100%)
A34: жовтень 2026 | D34: =ROUND(ROUND(B34*C34,2)*1.2,2) -> 0 | F34: =D34-E34 -> 0 | G34: =IF(ISERROR(E34/D34*100%),"",E34/D34*100%)
A35: листопад 2026 | D35: =ROUND(ROUND(B35*C35,2)*1.2,2) -> 0 | F35: =D35-E35 -> 0 | G35: =IF(ISERROR(E35/D35*100%),"",E35/D35*100%)
A36: грудень 2026 | D36: =ROUND(ROUND(B36*C36,2)*1.2,2) -> 0 | F36: =D36-E36 -> 0 | G36: =IF(ISERROR(E36/D36*100%),"",E36/D36*100%)
A37: ВСЬОГО за 2026 рік: | B37: =SUM(B25:B36) -> 28770 | D37: =SUM(D25:D36) -> 24544867 | E37: =SUM(E25:E36) -> 18382445 | F37: =SUM(F25:F36) -> 6162421.7 | G37: =IF(ISERROR(E37/D37*100%),"",E37/D37*100%) -> 0.74893236 | L37: =SUM(L25:L36) -> 18382445
