Workbook

Sheet ВЕРЕСЕНЬ_2025
A1: ЗВІТ з купівлі-продажу електроенергії УЗЕ ТОВ ”ЗНАМЕНСЬКА БЕСС”- 10,32180 МВт*год на ринках електроенергії РДН/ВДР та у балансуючій групі КНЕСС у вересні 2025 року | G1: ПРИВЕДЕННЯ РОЗРАХУНКІВ у відповідність до АКТІВ | J1: Похибка по середньозваженій ціні
A3: ОПЕРАЦІЯ | B3: Обсяг, МВт*год | C3: Середньозважена ціна, грн | D3: Вартість без ПДВ, грн | E3: Вартість з ПДВ, грн | G3: коригування без ПДВ | H3: коригування з ПДВ
A4: Купівля електроенергії: | B4: =SUM(B6:B9) -> 117.495 | C4: =D4/B4 -> 5184.0544 | D4: =SUM(D6:D9) -> 609100.47 | E4: =SUM(E6:E9) -> 730920.57 | J4: =B4*C4-D4 -> 0
A5: у т.ч.
A6: постачання активної електроенергії (КНЕСС) | B6: 37.26 | C6: 6155.315 | D6: =B6*C6+G6 -> 229347.04 | E6: =ROUND((D6*20%),2)+D6+H6 -> 275216.45
A7: на ринку РДН | B7: 0 | C7: 0 | D7: =B7*C7+G7 -> 0 | E7: =ROUND((D7*20%),2)+D7+H7 -> 0
A8: на ринку ВДР | B8: 0 | C8: 0 | D8: =B8*C8+G8 -> 0 | E8: =ROUND((D8*20%),2)+D8+H8 -> 0
A9: електроенергія для врегулювання небалансів (КНЕСС) | B9: 80.235 | C9: 4733.0147 | D9: =B9*C9+G9 -> 379753.43 | E9: =ROUND((D9*20%),2)+D9+H9 -> 455704.12
A10: Продаж електроенергії | B10: =SUM(B12:B14) -> 63.495 | C10: =D10/B10 -> 6629.365 | D10: =SUM(D12:D14) -> 420931.53 | E10: =SUM(E12:E14) -> 505117.84 | J10: =B10*C10-D10 -> 0
A11: у т.ч.
A12: на ринку РДН | B12: 0 | C12: 0 | D12: =B12*C12+G12 -> 0 | E12: =ROUND((D12*20%),2)+D12+H12 -> 0
A13: на ринку ВДР | B13: 0 | C13: 0 | D13: =B13*C13+G13 -> 0 | E13: =ROUND((D13*20%),2)+D13+H13 -> 0
A14: електроенергія для врегулювання небалансів (КНЕСС) | B14: 63.495 | C14: 6629.365 | D14: =B14*C14+G14 -> 420931.53 | E14: =ROUND((D14*20%),2)+D14+H14 -> 505117.84
A15: САЛЬДО (продаж- купівля): | B15: =B10-B4 -> -54 | C15: =C10-C4 -> 1445.3106 | D15: =D10-D4 -> -188168.94 | E15: =E10-E4 -> -225802.73
A17: ЗВІТ з купівлі-продажу електроенергії УЗЕ ТОВ ”ОЛЕКСАНДРІЙСЬКА БЕСС”- 15,33776 МВт*год на ринках електроенергії РДН/ВДР та у балансуючій групі КНЕСС у вересні 2025 року
A19: ОПЕРАЦІЯ | B19: Обсяг, МВт*год | C19: Середньозважена ціна, грн | D19: Вартість без ПДВ, грн | E19: Вартість з ПДВ, грн
A20: Купівля електроенергії: | B20: =SUM(B22:B25) -> 295.424 | C20: =D20/B20 -> 5002.8382 | D20: =SUM(D22:D25) -> 1477958.5 | E20: =SUM(E22:E25) -> 1773550.2 | J20: =B20*C20-D20 -> 0
A21: у т.ч.
A22: постачання активної електроенергії (КНЕСС) | B22: 24.096 | C22: 6413.1897 | D22: =B22*C22+G22 -> 154532.22 | E22: =ROUND((D22*20%),2)+D22+H22 -> 185438.66
A23: на ринку РДН | B23: 0 | C23: 0 | D23: =B23*C23+G23 -> 0 | E23: =ROUND((D23*20%),2)+D23+H23 -> 0
A24: на ринку ВДР | B24: 0 | C24: 0 | D24: =B24*C24+G24 -> 0 | E24: =ROUND((D24*20%),2)+D24+H24 -> 0
A25: електроенергія для врегулювання небалансів (КНЕСС) | B25: 271.328 | C25: 4877.5882 | D25: =B25*C25+G25 -> 1323426.2 | E25: =ROUND((D25*20%),2)+D25+H25 -> 1588111.5
A26: Продаж електроенергії | B26: =SUM(B28:B30) -> 231.072 | C26: =D26/B26 -> 6382.7611 | D26: =SUM(D28:D30) -> 1474877.4 | E26: =SUM(E28:E30) -> 1769852.9 | J26: =B26*C26-D26 -> 0
A27: у т.ч.
A28: на ринку РДН | B28: 0 | C28: 0 | D28: =B28*C28+G28 -> 0 | E28: =ROUND((D28*20%),2)+D28+H28 -> 0
A29: на ринку ВДР | B29: 0 | C29: 0 | D29: =B29*C29+G29 -> 0 | E29: =ROUND((D29*20%),2)+D29+H29 -> 0
A30: електроенергія для врегулювання небалансів (КНЕСС) | B30: 231.072 | C30: 6382.7611 | D30: =B30*C30+G30 -> 1474877.4 | E30: =ROUND((D30*20%),2)+D30+H30 -> 1769852.9
A31: САЛЬДО (продаж- купівля): | B31: =B26-B20 -> -64.352 | C31: =C26-C20 -> 1379.9229 | D31: =D26-D20 -> -3081.0925 | E31: =E26-E20 -> -3697.3025

Sheet ЖОВТЕНЬ_2025
A1: ЗВІТ з купівлі-продажу електроенергії УЗЕ ТОВ ”ЗНАМЕНСЬКА БЕСС”- 10,32180 МВт*год на ринках електроенергії РДН/ВДР та у балансуючій групі КНЕСС у жовтні 2025 року | G1: ПРИВЕДЕННЯ РОЗРАХУНКІВ у відповідність до АКТІВ | J1: Похибка по середньозваженій ціні
A3: ОПЕРАЦІЯ | B3: Обсяг, МВт*год | C3: Середньозважена ціна, грн | D3: Вартість без ПДВ, грн | E3: Вартість з ПДВ, грн | G3: коригування без ПДВ | H3: коригування з ПДВ
A4: Купівля електроенергії: | B4: =SUM(B6:B9) -> 221.75 | C4: =D4/B4 -> 4817.3397 | D4: =SUM(D6:D9) -> 1068245.1 | E4: =SUM(E6:E9) -> 1281894.1 | J4: =B4*C4-D4 -> 0
A5: у т.ч.
A6: постачання активної електроенергії (КНЕСС) | B6: 0 | C6: 0 | D6: =B6*C6+G6 -> 0 | E6: =ROUND((D6*20%),2)+D6+H6 -> 0
A7: на ринку РДН | B7: 0 | C7: 0 | D7: =B7*C7+G7 -> 0 | E7: =ROUND((D7*20%),2)+D7+H7 -> 0
A8: на ринку ВДР | B8: 68 | C8: 2045.4657 | D8: =B8*C8+G8 -> 139091.69 | E8: =ROUND((D8*20%),2)+D8+H8 -> 166910.03 | G8: 0.02
A9: електроенергія для врегулювання небалансів (КНЕСС) | B9: 153.75 | C9: 6043.274 | D9: =B9*C9+G9 -> 929153.38 | E9: =ROUND((D9*20%),2)+D9+H9 -> 1114984.1
A10: Продаж електроенергії | B10: =SUM(B12:B14) -> 171.665 | C10: =D10/B10 -> 10240.891 | D10: =SUM(D12:D14) -> 1758002.6 | E10: =SUM(E12:E14) -> 2109603.1 | J10: =B10*C10-D10 -> 0
A11: у т.ч.
A12: на ринку РДН | B12: 30 | C12: 14860.024 | D12: =B12*C12+G12 -> 445800.72 | E12: =ROUND((D12*20%),2)+D12+H12 -> 534960.86
A13: на ринку ВДР | B13: 45.3 | C13: 10143.8 | D13: =B13*C13+G13 -> 459514.15 | E13: =ROUND((D13*20%),2)+D13+H13 -> 551416.98 | G13: -0.01
A14: електроенергія для врегулювання небалансів (КНЕСС) | B14: 96.365 | C14: 8848.5211 | D14: =B14*C14+G14 -> 852687.74 | E14: =ROUND((D14*20%),2)+D14+H14 -> 1023225.3
A15: САЛЬДО (продаж- купівля): | B15: =B10-B4 -> -50.085 | C15: =C10-C4 -> 5423.5517 | D15: =D10-D4 -> 689757.54 | E15: =E10-E4 -> 827709.04
A17: ЗВІТ з купівлі-продажу електроенергії УЗЕ ТОВ ”ОЛЕКСАНДРІЙСЬКА БЕСС”- 15,33776 МВт*год на ринках електроенергії РДН/ВДР та у балансуючій групі КНЕСС у жовтні 2025 року
A19: ОПЕРАЦІЯ | B19: Обсяг, МВт*год | C19: Середньозважена ціна, грн | D19: Вартість без ПДВ, грн | E19: Вартість з ПДВ, грн
A20: Купівля електроенергії: | B20: =SUM(B22:B25) -> 289.092 | C20: =D20/B20 -> 4665.8599 | D20: =SUM(D22:D25) -> 1348862.8 | E20: =SUM(E22:E25) -> 1618635.3 | J20: =B20*C20-D20 -> 0
A21: у т.ч.
A22: постачання активної електроенергії (КНЕСС) | B22: 0 | C22: 0 | D22: =B22*C22+G22 -> 0 | E22: =ROUND((D22*20%),2)+D22+H22 -> 0
A23: на ринку РДН | B23: 0 | C23: 0 | D23: =B23*C23+G23 -> 0 | E23: =ROUND((D23*20%),2)+D23+H23 -> 0
A24: на ринку ВДР | B24: 92 | C24: 2086.6125 | D24: =B24*C24+G24 -> 191968.37 | E24: =ROUND((D24*20%),2)+D24+H24 -> 230362.04 | G24: 0.02
A25: електроенергія для врегулювання небалансів (КНЕСС) | B25: 197.092 | C25: 5869.8192 | D25: =B25*C25+G25 -> 1156894.4 | E25: =ROUND((D25*20%),2)+D25+H25 -> 1388273.3
A26: Продаж електроенергії | B26: =SUM(B28:B30) -> 224.996 | C26: =D26/B26 -> 10656.498 | D26: =SUM(D28:D30) -> 2397669.4 | E26: =SUM(E28:E30) -> 2877203.3 | J26: =B26*C26-D26 -> 0
A27: у т.ч.
A28: на ринку РДН | B28: 43.2 | C28: 14834.848 | D28: =B28*C28+G28 -> 640865.36 | E28: =ROUND((D28*20%),2)+D28+H28 -> 769038.43 | G28: -0.07
A29: на ринку ВДР | B29: 52.8 | C29: 10711.785 | D29: =B29*C29+G29 -> 565582.24 | E29: =ROUND((D29*20%),2)+D29+H29 -> 678698.69 | G29: 0.01
A30: електроенергія для врегулювання небалансів (КНЕСС) | B30: 128.996 | C30: 9234.5641 | D30: =B30*C30+G30 -> 1191221.8 | E30: =ROUND((D30*20%),2)+D30+H30 -> 1429466.2
A31: САЛЬДО (продаж- купівля): | B31: =B26-B20 -> -64.096 | C31: =C26-C20 -> 5990.6381 | D31: =D26-D20 -> 1048806.7 | E31: =E26-E20 -> 1258568

Sheet ЛИСТОПАД_2025
A1: ЗВІТ з купівлі-продажу електроенергії УЗЕ ТОВ ”ЗНАМЕНСЬКА БЕСС”- 10,32180 МВт*год на ринках електроенергії РДН/ВДР та у балансуючій групі КНЕСС у листопаді 2025 року
A3: ОПЕРАЦІЯ | B3: Обсяг, МВт*год | C3: Середньозважена ціна, грн | D3: Вартість без ПДВ, грн | E3: Вартість з ПДВ, грн
A4: Купівля електроенергії: | B4: =SUM(B6:B9) -> 271.14 | C4: =IF(ISERROR(D4/B4),0,D4/B4) -> 4476.876 | D4: =SUM(D6:D9) -> 1213860.2 | E4: =SUM(E6:E9) -> 1456632.2
A5: у т.ч.
A6: постачання активної електроенергії (КНЕСС) | B6: 0 | C6: 0 | D6: =B6*C6 -> 0 | E6: =ROUND((D6*20%),2)+D6 -> 0
A7: на ринку РДН | B7: 7.8 | C7: 6666.4462 | D7: =B7*C7 -> 51998.28 | E7: =ROUND((D7*20%),2)+D7 -> 62397.94
A8: на ринку ВДР | B8: 170.5 | C8: 2040.4655 | D8: =B8*C8 -> 347899.37 | E8: =ROUND((D8*20%),2)+D8 -> 417479.24
A9: електроенергія для врегулювання небалансів (КНЕСС) | B9: 92.84 | C9: 8767.3687 | D9: =B9*C9 -> 813962.51 | E9: =ROUND((D9*20%),2)+D9 -> 976755.01
A10: Продаж електроенергії | B10: =SUM(B12:B14) -> 224.325 | C10: =IF(ISERROR(D10/B10),0,D10/B10) -> 11040.662 | D10: =SUM(D12:D14) -> 2476696.5 | E10: =SUM(E12:E14) -> 2972035.8
A11: у т.ч.
A12: на ринку РДН | B12: 104.1 | C12: 14457.288 | D12: =B12*C12 -> 1505003.7 | E12: =ROUND((D12*20%),2)+D12 -> 1806004.4
A13: на ринку ВДР | B13: 64.5 | C13: 11213.333 | D13: =B13*C13 -> 723259.97 | E13: =ROUND((D13*20%),2)+D13 -> 867911.96
A14: електроенергія для врегулювання небалансів (КНЕСС) | B14: 55.725 | C14: 4458.1938 | D14: =B14*C14 -> 248432.85 | E14: =ROUND((D14*20%),2)+D14 -> 298119.42
A15: САЛЬДО (продаж- купівля): | B15: =B10-B4 -> -46.815 | C15: =C10-C4 -> 6563.786 | D15: =D10-D4 -> 1262836.3 | E15: =E10-E4 -> 1515403.6
A17: ЗВІТ з купівлі-продажу електроенергії УЗЕ ТОВ ”ОЛЕКСАНДРІЙСЬКА БЕСС”- 15,33776 МВт*год на ринках електроенергії РДН/ВДР та у балансуючій групі КНЕСС у листопаді 2025 року
A19: ОПЕРАЦІЯ | B19: Обсяг, МВт*год | C19: Середньозважена ціна, грн | D19: Вартість без ПДВ, грн | E19: Вартість з ПДВ, грн
A20: Купівля електроенергії: | B20: =SUM(B22:B25) -> 361.672 | C20: =IF(ISERROR(D20/B20),0,D20/B20) -> 4245.7609 | D20: =SUM(D22:D25) -> 1535572.8 | E20: =SUM(E22:E25) -> 1842687.4
A21: у т.ч.
A22: постачання активної електроенергії (КНЕСС) | B22: 0 | C22: 0 | D22: =B22*C22 -> 0 | E22: =ROUND((D22*20%),2)+D22 -> 0
A23: на ринку РДН | B23: 8.6 | C23: 6666.9884 | D23: =B23*C23 -> 57336.1 | E23: =ROUND((D23*20%),2)+D23 -> 68803.32
A24: на ринку ВДР | B24: 239.9 | C24: 2048.6764 | D24: =B24*C24 -> 491477.47 | E24: =ROUND((D24*20%),2)+D24 -> 589772.96
A25: електроенергія для врегулювання небалансів (КНЕСС) | B25: 113.172 | C25: 8719.1112 | D25: =B25*C25 -> 986759.25 | E25: =ROUND((D25*20%),2)+D25 -> 1184111.1
A26: Продаж електроенергії | B26: =SUM(B28:B30) -> 298.984 | C26: =IF(ISERROR(D26/B26),0,D26/B26) -> 11352.033 | D26: =SUM(D28:D30) -> 3394076.2 | E26: =SUM(E28:E30) -> 4072891.4
A27: у т.ч.
A28: на ринку РДН | B28: 147.3 | C28: 14438.575 | D28: =B28*C28 -> 2126802.1 | E28: =ROUND((D28*20%),2)+D28 -> 2552162.6
A29: на ринку ВДР | B29: 88.3 | C29: 10928.729 | D29: =B29*C29 -> 965006.8 | E29: =ROUND((D29*20%),2)+D29 -> 1158008.2
A30: електроенергія для врегулювання небалансів (КНЕСС) | B30: 63.384 | C30: 4768.8256 | D30: =B30*C30 -> 302267.24 | E30: =ROUND((D30*20%),2)+D30 -> 362720.69
A31: САЛЬДО (продаж- купівля): | B31: =B26-B20 -> -62.688 | C31: =C26-C20 -> 7106.2719 | D31: =D26-D20 -> 1858503.3 | E31: =E26-E20 -> 2230204

Sheet ГРУДЕНЬ_2025
A1: ЗВІТ з купівлі-продажу електроенергії УЗЕ ТОВ ”ЗНАМЕНСЬКА БЕСС”- 10,32180 МВт*год на ринках електроенергії РДН/ВДР та у балансуючій групі КНЕСС у грудні 2025 року
A3: ОПЕРАЦІЯ | B3: Обсяг, МВт*год | C3: Середньозважена ціна, грн | D3: Вартість без ПДВ, грн | E3: Вартість з ПДВ, грн
A4: Купівля електроенергії: | B4: =SUM(B6:B9) -> 260.585 | C4: =IF(ISERROR(D4/B4),0,D4/B4) -> 5220.7799 | D4: =SUM(D6:D9) -> 1360456.9 | E4: =SUM(E6:E9) -> 1632548.3
A5: у т.ч.
A6: постачання активної електроенергії (КНЕСС) | B6: 0 | C6: 0 | D6: =B6*C6 -> 0 | E6: =ROUND((D6*20%),2)+D6 -> 0
A7: на ринку РДН | B7: 91.7 | C7: 3396.1527 | D7: =B7*C7 -> 311427.2 | E7: =ROUND((D7*20%),2)+D7 -> 373712.64
A8: на ринку ВДР | B8: 35.3 | C8: 3437.6907 | D8: =B8*C8 -> 121350.48 | E8: =ROUND((D8*20%),2)+D8 -> 145620.58
A9: електроенергія для врегулювання небалансів (КНЕСС) | B9: 133.585 | C9: 6944.4867 | D9: =B9*C9 -> 927679.26 | E9: =ROUND((D9*20%),2)+D9 -> 1113215.1
A10: Продаж електроенергії | B10: =SUM(B12:B14) -> 209.405 | C10: =IF(ISERROR(D10/B10),0,D10/B10) -> 10306.553 | D10: =SUM(D12:D14) -> 2158243.8 | E10: =SUM(E12:E14) -> 2589892.5
A11: у т.ч.
A12: на ринку РДН | B12: 89.4 | C12: 13208.967 | D12: =B12*C12 -> 1180881.7 | E12: =ROUND((D12*20%),2)+D12 -> 1417058
A13: на ринку ВДР | B13: 38.5 | C13: 11498.006 | D13: =B13*C13 -> 442673.25 | E13: =ROUND((D13*20%),2)+D13 -> 531207.9
A14: електроенергія для врегулювання небалансів (КНЕСС) | B14: 81.505 | C14: 6560.1968 | D14: =B14*C14 -> 534688.84 | E14: =ROUND((D14*20%),2)+D14 -> 641626.61
A15: САЛЬДО (продаж- купівля): | B15: =B10-B4 -> -51.18 | C15: =C10-C4 -> 5085.7732 | D15: =D10-D4 -> 797786.81 | E15: =E10-E4 -> 957344.17
A17: ЗВІТ з купівлі-продажу електроенергії УЗЕ ТОВ ”ОЛЕКСАНДРІЙСЬКА БЕСС”- 15,33776 МВт*год на ринках електроенергії РДН/ВДР та у балансуючій групі КНЕСС у грудні 2025 року
A19: ОПЕРАЦІЯ | B19: Обсяг, МВт*год | C19: Середньозважена ціна, грн | D19: Вартість без ПДВ, грн | E19: Вартість з ПДВ, грн
A20: Купівля електроенергії: | B20: =SUM(B22:B25) -> 353.996 | C20: =IF(ISERROR(D20/B20),0,D20/B20) -> 5056.0548 | D20: =SUM(D22:D25) -> 1789823.2 | E20: =SUM(E22:E25) -> 2147787.8
A21: у т.ч.
A22: постачання активної електроенергії (КНЕСС) | B22: 0 | C22: 0 | D22: =B22*C22 -> 0 | E22: =ROUND((D22*20%),2)+D22 -> 0
A23: на ринку РДН | B23: 130.2 | C23: 3471.1336 | D23: =B23*C23 -> 451941.6 | E23: =ROUND((D23*20%),2)+D23 -> 542329.92
A24: на ринку ВДР | B24: 51.1 | C24: 3741.672 | D24: =B24*C24 -> 191199.44 | E24: =ROUND((D24*20%),2)+D24 -> 229439.33
A25: електроенергія для врегулювання небалансів (КНЕСС) | B25: 172.696 | C25: 6639.8883 | D25: =B25*C25 -> 1146682.1 | E25: =ROUND((D25*20%),2)+D25 -> 1376018.6
A26: Продаж електроенергії | B26: =SUM(B28:B30) -> 287.58 | C26: =IF(ISERROR(D26/B26),0,D26/B26) -> 10600.983 | D26: =SUM(D28:D30) -> 3048630.7 | E26: =SUM(E28:E30) -> 3658356.8
A27: у т.ч.
A28: на ринку РДН | B28: 130.5 | C28: 13186.202 | D28: =B28*C28 -> 1720799.3 | E28: =ROUND((D28*20%),2)+D28 -> 2064959.2
A29: на ринку ВДР | B29: 52.3 | C29: 11542.37 | D29: =B29*C29 -> 603665.96 | E29: =ROUND((D29*20%),2)+D29 -> 724399.15
A30: електроенергія для врегулювання небалансів (КНЕСС) | B30: 104.78 | C30: 6911.294 | D30: =B30*C30 -> 724165.38 | E30: =ROUND((D30*20%),2)+D30 -> 868998.46
A31: САЛЬДО (продаж- купівля): | B31: =B26-B20 -> -66.416 | C31: =C26-C20 -> 5544.9281 | D31: =D26-D20 -> 1258807.5 | E31: =E26-E20 -> 1510569

Sheet СІЧЕНЬ_2026
A1: ЗВІТ з купівлі-продажу електроенергії УЗЕ ТОВ ”ЗНАМЕНСЬКА БЕСС”- 10,32180 МВт*год на ринках електроенергії РДН/ВДР та у балансуючій групі КНЕСС у січні 2026 року
A3: ОПЕРАЦІЯ | B3: Обсяг, МВт*год | C3: Середньозважена ціна, грн | D3: Вартість без ПДВ, грн | E3: Вартість з ПДВ, грн
A4: Купівля електроенергії: | B4: =SUM(B6:B9) -> 308.85 | C4: =IF(ISERROR(D4/B4),0,D4/B4) -> 6828.5855 | D4: =SUM(D6:D9) -> 2109008.6 | E4: =SUM(E6:E9) -> 2530810.3
A5: у т.ч.
A6: постачання активної електроенергії (КНЕСС) | B6: 0 | C6: 0 | D6: =B6*C6 -> 0 | E6: =ROUND((D6*20%),2)+D6 -> 0
A7: на ринку РДН | B7: 143.8 | C7: 5285.2446 | D7: =B7*C7 -> 760018.18 | E7: =ROUND((ROUND((D7*20%),2)+D7),2) -> 912021.82
A8: на ринку ВДР | B8: 65.8 | C8: 5904.1769 | D8: =B8*C8 -> 388494.84 | E8: =ROUND((ROUND((D8*20%),2)+D8),2) -> 466193.81
A9: електроенергія для врегулювання небалансів (КНЕСС) | B9: 99.25 | C9: 9677.5375 | D9: =B9*C9 -> 960495.6 | E9: =ROUND((ROUND((D9*20%),2)+D9),2) -> 1152594.7
A10: Продаж електроенергії | B10: =SUM(B12:B14) -> 250.74 | C10: =IF(ISERROR(D10/B10),0,D10/B10) -> 11774.033 | D10: =SUM(D12:D14) -> 2952221.1 | E10: =SUM(E12:E14) -> 3542665.3
A11: у т.ч.
A12: на ринку РДН | B12: 127.9 | C12: 13110.541 | D12: =B12*C12 -> 1676838.2 | E12: =ROUND((ROUND((D12*20%),2)+D12),2) -> 2012205.8
A13: на ринку ВДР | B13: 67.1 | C13: 12707.657 | D13: =B13*C13 -> 852683.8 | E13: =ROUND((ROUND((D13*20%),2)+D13),2) -> 1023220.6
A14: електроенергія для врегулювання небалансів (КНЕСС) | B14: 55.74 | C14: 7583.4073 | D14: =B14*C14 -> 422699.12 | E14: =ROUND((ROUND((D14*20%),2)+D14),2) -> 507238.94
A15: САЛЬДО (продаж- купівля): | B15: =B10-B4 -> -58.11 | C15: =C10-C4 -> 4945.4477 | D15: =D10-D4 -> 843212.45 | E15: =E10-E4 -> 1011854.9
A17: ЗВІТ з купівлі-продажу електроенергії УЗЕ ТОВ ”ОЛЕКСАНДРІЙСЬКА БЕСС”- 15,33776 МВт*год на ринках електроенергії РДН/ВДР та у балансуючій групі КНЕСС у січні 2026 року
A19: ОПЕРАЦІЯ | B19: Обсяг, МВт*год | C19: Середньозважена ціна, грн | D19: Вартість без ПДВ, грн | E19: Вартість з ПДВ, грн
A20: Купівля електроенергії: | B20: =SUM(B22:B25) -> 423.416 | C20: =IF(ISERROR(D20/B20),0,D20/B20) -> 6727.2913 | D20: =SUM(D22:D25) -> 2848442.8 | E20: =SUM(E22:E25) -> 3418131.3
A21: у т.ч.
A22: постачання активної електроенергії (КНЕСС) | B22: 0 | C22: 0 | D22: =B22*C22 -> 0 | E22: =ROUND((D22*20%),2)+D22 -> 0
A23: на ринку РДН | B23: 207.2 | C23: 5318.0753 | D23: =B23*C23 -> 1101905.2 | E23: =ROUND((ROUND((D23*20%),2)+D23),2) -> 1322286.2
A24: на ринку ВДР | B24: 93.6 | C24: 6052.35 | D24: =B24*C24 -> 566499.96 | E24: =ROUND((ROUND((D24*20%),2)+D24),2) -> 679799.95
A25: електроенергія для врегулювання небалансів (КНЕСС) | B25: 122.616 | C25: 9623.8468 | D25: =B25*C25 -> 1180037.6 | E25: =ROUND((ROUND((D25*20%),2)+D25),2) -> 1416045.1
A26: Продаж електроенергії | B26: =SUM(B28:B30) -> 346.456 | C26: =IF(ISERROR(D26/B26),0,D26/B26) -> 11877.21 | D26: =SUM(D28:D30) -> 4114930.5 | E26: =SUM(E28:E30) -> 4937916.6
A27: у т.ч.
A28: на ринку РДН | B28: 184.3 | C28: 13124.012 | D28: =B28*C28 -> 2418755.4 | E28: =ROUND((ROUND((D28*20%),2)+D28),2) -> 2902506.5
A29: на ринку ВДР | B29: 89.9 | C29: 12480.049 | D29: =B29*C29 -> 1121956.4 | E29: =ROUND((ROUND((D29*20%),2)+D29),2) -> 1346347.7
A30: електроенергія для врегулювання небалансів (КНЕСС) | B30: 72.256 | C30: 7947.0039 | D30: =B30*C30 -> 574218.71 | E30: =ROUND((ROUND((D30*20%),2)+D30),2) -> 689062.45
A31: САЛЬДО (продаж- купівля): | B31: =B26-B20 -> -76.96 | C31: =C26-C20 -> 5149.9183 | D31: =D26-D20 -> 1266487.8 | E31: =E26-E20 -> 1519785.3

Sheet ЛЮТИЙ_2026
A1: ЗВІТ з купівлі-продажу електроенергії УЗЕ ТОВ ”ЗНАМЕНСЬКА БЕСС”- 10,32180 МВт*год на ринках електроенергії РДН/ВДР та у балансуючій групі КНЕСС у лютому 2026 року
A3: ОПЕРАЦІЯ | B3: Обсяг, МВт*год | C3: Середньозважена ціна, грн | D3: Вартість без ПДВ, грн | E3: Вартість з ПДВ, грн
A4: Купівля електроенергії: | B4: =SUM(B6:B9) -> 329.025 | C4: =IF(ISERROR(D4/B4),0,D4/B4) -> 7062.4458 | D4: =SUM(D6:D9) -> 2323721.2 | E4: =SUM(E6:E9) -> 2788465.5
A5: у т.ч.
A6: постачання активної електроенергії (КНЕСС) | B6: 0 | C6: 0 | D6: =B6*C6 -> 0 | E6: =ROUND((D6*20%),2)+D6 -> 0
A7: на ринку РДН | B7: 0 | C7: 0 | D7: =B7*C7 -> 0 | E7: =ROUND((ROUND((D7*20%),2)+D7),2) -> 0
A8: на ринку ВДР | B8: 245.2 | C8: 5619.7252 | D8: =B8*C8 -> 1377956.6 | E8: =ROUND((ROUND((D8*20%),2)+D8),2) -> 1653548
A9: електроенергія для врегулювання небалансів (КНЕСС) | B9: 83.825 | C9: 11282.608 | D9: =B9*C9 -> 945764.6 | E9: =ROUND((ROUND((D9*20%),2)+D9),2) -> 1134917.5
A10: Продаж електроенергії | B10: =SUM(B12:B14) -> 281.49 | C10: =IF(ISERROR(D10/B10),0,D10/B10) -> 13229.903 | D10: =SUM(D12:D14) -> 3724085.4 | E10: =SUM(E12:E14) -> 4468902.5
A11: у т.ч.
A12: на ринку РДН | B12: 5 | C12: 14934.11 | D12: =B12*C12 -> 74670.55 | E12: =ROUND((ROUND((D12*20%),2)+D12),2) -> 89604.66
A13: на ринку ВДР | B13: 230.9 | C13: 13985.984 | D13: =B13*C13 -> 3229363.7 | E13: =ROUND((ROUND((D13*20%),2)+D13),2) -> 3875236.5
A14: електроенергія для врегулювання небалансів (КНЕСС) | B14: 45.59 | C14: 9213.6683 | D14: =B14*C14 -> 420051.14 | E14: =ROUND((ROUND((D14*20%),2)+D14),2) -> 504061.37
A15: САЛЬДО (продаж- купівля): | B15: =B10-B4 -> -47.535 | C15: =C10-C4 -> 6167.4572 | D15: =D10-D4 -> 1400364.2 | E15: =E10-E4 -> 1680437
A17: ЗВІТ з купівлі-продажу електроенергії УЗЕ ТОВ ”ОЛЕКСАНДРІЙСЬКА БЕСС”- 15,33776 МВт*год на ринках електроенергії РДН/ВДР та у балансуючій групі КНЕСС у лютому 2026 року
A19: ОПЕРАЦІЯ | B19: Обсяг, МВт*год | C19: Середньозважена ціна, грн | D19: Вартість без ПДВ, грн | E19: Вартість з ПДВ, грн
A20: Купівля електроенергії: | B20: =SUM(B22:B25) -> 422.796 | C20: =IF(ISERROR(D20/B20),0,D20/B20) -> 6981.6525 | D20: =SUM(D22:D25) -> 2951814.7 | E20: =SUM(E22:E25) -> 3542177.7
A21: у т.ч.
A22: постачання активної електроенергії (КНЕСС) | B22: 0 | C22: 0 | D22: =B22*C22 -> 0 | E22: =ROUND((D22*20%),2)+D22 -> 0
A23: на ринку РДН | B23: 0 | C23: 0 | D23: =B23*C23 -> 0 | E23: =ROUND((ROUND((D23*20%),2)+D23),2) -> 0
A24: на ринку ВДР | B24: 321.1 | C24: 5631.731 | D24: =B24*C24 -> 1808348.8 | E24: =ROUND((ROUND((D24*20%),2)+D24),2) -> 2170018.6
A25: електроенергія для врегулювання небалансів (КНЕСС) | B25: 101.696 | C25: 11243.962 | D25: =B25*C25 -> 1143465.9 | E25: =ROUND((ROUND((D25*20%),2)+D25),2) -> 1372159.1
A26: Продаж електроенергії | B26: =SUM(B28:B30) -> 362.124 | C26: =IF(ISERROR(D26/B26),0,D26/B26) -> 13247.665 | D26: =SUM(D28:D30) -> 4797297.5 | E26: =SUM(E28:E30) -> 5756757
A27: у т.ч.
A28: на ринку РДН | B28: 7.4 | C28: 14910.961 | D28: =B28*C28 -> 110341.11 | E28: =ROUND((ROUND((D28*20%),2)+D28),2) -> 132409.33
A29: на ринку ВДР | B29: 301.2 | C29: 13886.663 | D29: =B29*C29 -> 4182662.8 | E29: =ROUND((ROUND((D29*20%),2)+D29),2) -> 5019195.3
A30: електроенергія для врегулювання небалансів (КНЕСС) | B30: 53.524 | C30: 9421.8222 | D30: =B30*C30 -> 504293.61 | E30: =ROUND((ROUND((D30*20%),2)+D30),2) -> 605152.33
A31: САЛЬДО (продаж- купівля): | B31: =B26-B20 -> -60.672 | C31: =C26-C20 -> 6266.0127 | D31: =D26-D20 -> 1845482.8 | E31: =E26-E20 -> 2214579.3

Sheet БЕРЕЗЕНЬ_2026
A1: ЗВІТ з купівлі-продажу електроенергії УЗЕ ТОВ ”ЗНАМЕНСЬКА БЕСС”- 10,32180 МВт*год на ринках електроенергії РДН/ВДР та у балансуючій групі КНЕСС у березні 2026 року
A3: ОПЕРАЦІЯ | B3: Обсяг, МВт*год | C3: Середньозважена ціна, грн/МВт*год | D3: Вартість без ПДВ, грн | E3: Вартість з ПДВ, грн | G3: Для себя
A4: Купівля електроенергії: | B4: =SUM(B6:B10) -> 440.15833 | C4: =IF(ISERROR(D4/B4),0,D4/B4) -> 3742.9309 | D4: =SUM(D6:D10) -> 1647482.2 | E4: =SUM(E6:E10) -> 1976978.7 | G4: =SUM(G6:G10) -> 441.05833
A5: у т.ч.
A6: постачання активної електроенергії (КНЕСС) | B6: 0 | C6: 0 | D6: =B6*C6 -> 0 | E6: =ROUND((D6*20%),2)+D6 -> 0
A7: на ринку РДН | B7: 13.8 | C7: 1225 | D7: =B7*C7 -> 16905 | E7: =ROUND((ROUND((D7*20%),2)+D7),2) -> 20286 | G7: =B7 -> 13.8
A8: на ринку ВДР | B8: 261.4 | C8: 3445.0166 | D8: =B8*C8 -> 900527.34 | E8: =ROUND((ROUND((D8*20%),2)+D8),2) -> 1080632.8 | G8: =B8 -> 261.4
A9: купівля балансуючої електроенергії (НЕК "УКРЕНЕРГО") | B9: 70.833335 | C9: 0.24903529 | D9: =B9*C9 -> 17.64 | E9: =ROUND((ROUND((D9*20%),2)+D9),2) -> 21.17 | G9: =B9 -> 70.833335
A10: електроенергія для врегулювання небалансів (КНЕСС) | B10: 94.124999 | C10: 7755.987 | D10: =B10*C10 -> 730032.27 | E10: =ROUND((ROUND((D10*20%),2)+D10),2) -> 876038.72 | G10: 95.024999 | H10: =B10-G10 -> -0.9
A11: Продаж електроенергії | B11: =SUM(B13:B16) -> 371.72833 | C11: =IF(ISERROR(D11/B11),0,D11/B11) -> 11043.307 | D11: =SUM(D13:D16) -> 4105110 | E11: =SUM(E13:E16) -> 4926132 | G11: =SUM(G13:G16) -> 372.62833
A12: у т.ч.
A13: на ринку РДН | B13: 137.9 | C13: 14062.764 | D13: =B13*C13 -> 1939255.1 | E13: =ROUND((ROUND((D13*20%),2)+D13),2) -> 2327106.1 | G13: =B13 -> 137.9
A14: на ринку ВДР | B14: 175.2 | C14: 10898.759 | D14: =B14*C14 -> 1909462.6 | E14: =ROUND((ROUND((D14*20%),2)+D14),2) -> 2291355.1 | G14: =B14 -> 175.2
A15: продаж балансуючої електроенергії (НЕК "УКРЕНЕРГО") | B15: 0 | C15: 0 | D15: =B15*C15 -> 0 | E15: =ROUND((ROUND((D15*20%),2)+D15),2) -> 0
A16: електроенергія для врегулювання небалансів (КНЕСС) | B16: 58.628334 | C16: 4373.1811 | D16: =B16*C16 -> 256392.32 | E16: =ROUND((ROUND((D16*20%),2)+D16),2) -> 307670.78 | G16: 59.528334 | H16: =B16-G16 -> -0.9
A17: САЛЬДО (продаж- купівля): | B17: =B11-B4 -> -68.43 | C17: =C11-C4 -> 7300.3756 | D17: =D11-D4 -> 2457627.7 | E17: =E11-E4 -> 2949153.2 | G17: =G11-G4 -> -68.43
A19: ЗВІТ з купівлі-продажу електроенергії УЗЕ ТОВ ”ОЛЕКСАНДРІЙСЬКА БЕСС”- 15,33776 МВт*год на ринках електроенергії РДН/ВДР та у балансуючій групі КНЕСС у березні 2026 року
A21: ОПЕРАЦІЯ | B21: Обсяг, МВт*год | C21: Середньозважена ціна, грн/МВт*год | D21: Вартість без ПДВ, грн | E21: Вартість з ПДВ, грн
A22: Купівля електроенергії: | B22: =SUM(B24:B28) -> 560.28467 | C22: =IF(ISERROR(D22/B22),0,D22/B22) -> 3708.6223 | D22: =SUM(D24:D28) -> 2077884.2 | E22: =SUM(E24:E28) -> 2493461.1 | G22: =SUM(G24:G28) -> 562.14867
A23: у т.ч.
A24: постачання активної електроенергії (КНЕСС) | B24: 0 | C24: 0 | D24: =B24*C24 -> 0 | E24: =ROUND((D24*20%),2)+D24 -> 0
A25: на ринку РДН | B25: 19.8 | C25: 1200 | D25: =B25*C25 -> 23760 | E25: =ROUND((ROUND((D25*20%),2)+D25),2) -> 28512 | G25: =B25 -> 19.8
A26: на ринку ВДР | B26: 341.1 | C26: 3426.4677 | D26: =B26*C26 -> 1168768.1 | E26: =ROUND((ROUND((D26*20%),2)+D26),2) -> 1402521.7 | G26: =B26 -> 341.1
A27: купівля балансуючої електроенергії (НЕК "УКРЕНЕРГО") | B27: 80.850001 | C27: 0.9946815 | D27: =B27*C27 -> 80.42 | E27: =ROUND((ROUND((D27*20%),2)+D27),2) -> 96.5 | G27: =B27 -> 80.850001
A28: електроенергія для врегулювання небалансів (КНЕСС) | B28: 118.53467 | C28: 7468.496 | D28: =B28*C28 -> 885275.68 | E28: =ROUND((ROUND((D28*20%),2)+D28),2) -> 1062330.8 | G28: 120.39867 | H28: =B28-G28 -> -1.864
A29: Продаж електроенергії | B29: =SUM(B31:B34) -> 471.72467 | C29: =IF(ISERROR(D29/B29),0,D29/B29) -> 11216.654 | D29: =SUM(D31:D34) -> 5291172.2 | E29: =SUM(E31:E34) -> 6349406.6 | G29: =SUM(G31:G34) -> 473.58867
A30: у т.ч.
A31: на ринку РДН | B31: 191.3 | C31: 13976.236 | D31: =B31*C31 -> 2673654 | E31: =ROUND((ROUND((D31*20%),2)+D31),2) -> 3208384.8 | G31: =B31 -> 191.3
A32: на ринку ВДР | B32: 210.7 | C32: 10763.087 | D32: =B32*C32 -> 2267782.4 | E32: =ROUND((ROUND((D32*20%),2)+D32),2) -> 2721338.9 | G32: =B32 -> 210.7
A33: продаж балансуючої електроенергії (НЕК "УКРЕНЕРГО") | B33: 0 | C33: 0 | D33: =B33*C33 -> 0 | E33: =ROUND((ROUND((D33*20%),2)+D33),2) -> 0
A34: електроенергія для врегулювання небалансів (КНЕСС) | B34: 69.724667 | C34: 5015.9537 | D34: =B34*C34 -> 349735.7 | E34: =ROUND((ROUND((D34*20%),2)+D34),2) -> 419682.84 | G34: 71.588667 | H34: =B34-G34 -> -1.864
A35: САЛЬДО (продаж- купівля): | B35: =B29-B22 -> -88.56 | C35: =C29-C22 -> 7508.0313 | D35: =D29-D22 -> 3213287.9 | E35: =E29-E22 -> 3855945.5 | G35: =G29-G22 -> -88.56

Sheet РАЗОМ
A1: ЗВІТ з купівлі-продажу електроенергії УЗЕ ТОВ ”ЗНАМЕНСЬКА БЕСС”- 10,32180 МВт*год на ринках електроенергії РДН/ВДР та у балансуючій групі КНЕСС у вересні 2025 року | F1: ЗВІТ з купівлі-продажу електроенергії УЗЕ ТОВ ”ЗНАМЕНСЬКА БЕСС”- 10,32180 МВт*год на ринках електроенергії РДН/ВДР та у балансуючій групі КНЕСС у жовтні 2025 року | K1: ЗВІТ з купівлі-продажу електроенергії УЗЕ ТОВ ”ЗНАМЕНСЬКА БЕСС”- 10,32180 МВт*год на ринках електроенергії РДН/ВДР та у балансуючій групі КНЕСС у листопаді 2025 року | P1: ЗВІТ з купівлі-продажу електроенергії УЗЕ ТОВ ”ЗНАМЕНСЬКА БЕСС”- 10,32180 МВт*год на ринках електроенергії РДН/ВДР та у балансуючій групі КНЕСС у грудні 2025 року | U1: ЗВІТ з купівлі-продажу електроенергії УЗЕ ТОВ ”ЗНАМЕНСЬКА БЕСС”- 10,32180 МВт*год на ринках електроенергії РДН/ВДР та у балансуючій групі КНЕСС у січні 2026 року | Z1: ЗВІТ з купівлі-продажу електроенергії УЗЕ ТОВ ”ЗНАМЕНСЬКА БЕСС”- 10,32180 МВт*год на ринках електроенергії РДН/ВДР та у балансуючій групі КНЕСС у лютому 2026 року
A3: ОПЕРАЦІЯ | B3: Обсяг, МВт*год | C3: Середньозважена ціна, грн | D3: Вартість без ПДВ, грн | E3: Вартість з ПДВ, грн | F3: ОПЕРАЦІЯ | G3: Обсяг, МВт*год | H3: Середньозважена ціна, грн | I3: Вартість без ПДВ, грн | J3: Вартість з ПДВ, грн | K3: ОПЕРАЦІЯ | L3: Обсяг, МВт*год | M3: Середньозважена ціна, грн | N3: Вартість без ПДВ, грн | O3: Вартість з ПДВ, грн | P3: ОПЕРАЦІЯ | Q3: Обсяг, МВт*год | R3: Середньозважена ціна, грн | S3: Вартість без ПДВ, грн | T3: Вартість з ПДВ, грн | U3: ОПЕРАЦІЯ | V3: Обсяг, МВт*год | W3: Середньозважена ціна, грн | X3: Вартість без ПДВ, грн | Y3: Вартість з ПДВ, грн | Z3: ОПЕРАЦІЯ | AA3: Обсяг, МВт*год | AB3: Середньозважена ціна, грн | AC3: Вартість без ПДВ, грн | AD3: Вартість з ПДВ, грн
A4: Купівля електроенергії: | B4: 117.495 | C4: 5184.0544 | D4: 609100.47 | E4: 730920.57 | F4: Купівля електроенергії: | G4: 221.75 | H4: 4817.3396 | I4: 1068245.1 | J4: 1281894.1 | K4: Купівля електроенергії: | L4: 271.14 | M4: 4476.876 | N4: 1213860.2 | O4: 1456632.2 | P4: Купівля електроенергії: | Q4: 260.585 | R4: 5220.7799 | S4: 1360456.9 | T4: 1632548.3 | U4: Купівля електроенергії: | V4: 308.85 | W4: 6828.5855 | X4: 2109008.6 | Y4: 2530810.3 | Z4: Купівля електроенергії: | AA4: 329.025 | AB4: 7062.4458 | AC4: 2323721.2 | AD4: 2788465.5
A5: у т.ч. | F5: у т.ч. | K5: у т.ч. | P5: у т.ч. | U5: у т.ч. | Z5: у т.ч.
A6: постачання активної електроенергії (КНЕСС) | B6: 37.26 | C6: 6155.315 | D6: 229347.04 | E6: 275216.45 | F6: постачання активної електроенергії (КНЕСС) | G6: 0 | H6: 0 | I6: 0 | J6: 0 | K6: постачання активної електроенергії (КНЕСС) | L6: 0 | M6: 0 | N6: 0 | O6: 0 | P6: постачання активної електроенергії (КНЕСС) | Q6: 0 | R6: 0 | S6: 0 | T6: 0 | U6: постачання активної електроенергії (КНЕСС) | V6: 0 | W6: 0 | X6: 0 | Y6: 0 | Z6: постачання активної електроенергії (КНЕСС) | AA6: 0 | AB6: 0 | AC6: 0 | AD6: 0
A7: на ринку РДН | B7: 0 | C7: 0 | D7: 0 | E7: 0 | F7: на ринку РДН | G7: 0 | H7: 0 | I7: 0 | J7: 0 | K7: на ринку РДН | L7: 7.8 | M7: 6666.4462 | N7: 51998.28 | O7: 62397.94 | P7: на ринку РДН | Q7: 91.7 | R7: 3396.1527 | S7: 311427.2 | T7: 373712.64 | U7: на ринку РДН | V7: 143.8 | W7: 5285.2446 | X7: 760018.18 | Y7: 912021.82 | Z7: на ринку РДН | AA7: 0 | AB7: 0 | AC7: 0 | AD7: 0
A8: на ринку ВДР | B8: 0 | C8: 0 | D8: 0 | E8: 0 | F8: на ринку ВДР | G8: 68 | H8: 2045.4657 | I8: 139091.67 | J8: 166910 | K8: на ринку ВДР | L8: 170.5 | M8: 2040.4655 | N8: 347899.37 | O8: 417479.24 | P8: на ринку ВДР | Q8: 35.3 | R8: 3437.6907 | S8: 121350.48 | T8: 145620.58 | U8: на ринку ВДР | V8: 65.8 | W8: 5904.1769 | X8: 388494.84 | Y8: 466193.81 | Z8: на ринку ВДР | AA8: 245.2 | AB8: 5619.7252 | AC8: 1377956.6 | AD8: 1653548
A9: електроенергія для врегулювання небалансів (КНЕСС) | B9: 80.235 | C9: 4733.0147 | D9: 379753.43 | E9: 455704.12 | F9: електроенергія для врегулювання небалансів (КНЕСС) | G9: 153.75 | H9: 6043.274 | I9: 929153.38 | J9: 1114984.1 | K9: електроенергія для врегулювання небалансів (КНЕСС) | L9: 92.84 | M9: 8767.3687 | N9: 813962.51 | O9: 976755.01 | P9: електроенергія для врегулювання небалансів (КНЕСС) | Q9: 133.585 | R9: 6944.4867 | S9: 927679.26 | T9: 1113215.1 | U9: електроенергія для врегулювання небалансів (КНЕСС) | V9: 99.25 | W9: 9677.5375 | X9: 960495.6 | Y9: 1152594.7 | Z9: електроенергія для врегулювання небалансів (КНЕСС) | AA9: 83.825 | AB9: 11282.608 | AC9: 945764.6 | AD9: 1134917.5
A10: Продаж електроенергії | B10: 63.495 | C10: 6629.365 | D10: 420931.53 | E10: 505117.84 | F10: Продаж електроенергії | G10: 171.665 | H10: 10240.891 | I10: 1758002.6 | J10: 2109603.1 | K10: Продаж електроенергії | L10: 224.325 | M10: 11040.662 | N10: 2476696.5 | O10: 2972035.8 | P10: Продаж електроенергії | Q10: 209.405 | R10: 10306.553 | S10: 2158243.8 | T10: 2589892.5 | U10: Продаж електроенергії | V10: 250.74 | W10: 11774.033 | X10: 2952221.1 | Y10: 3542665.3 | Z10: Продаж електроенергії | AA10: 281.49 | AB10: 13229.903 | AC10: 3724085.4 | AD10: 4468902.5
A11: у т.ч. | F11: у т.ч. | K11: у т.ч. | P11: у т.ч. | U11: у т.ч. | Z11: у т.ч.
A12: на ринку РДН | B12: 0 | C12: 0 | D12: 0 | E12: 0 | F12: на ринку РДН | G12: 30 | H12: 14860.024 | I12: 445800.72 | J12: 534960.86 | K12: на ринку РДН | L12: 104.1 | M12: 14457.288 | N12: 1505003.7 | O12: 1806004.4 | P12: на ринку РДН | Q12: 89.4 | R12: 13208.967 | S12: 1180881.7 | T12: 1417058 | U12: на ринку РДН | V12: 127.9 | W12: 13110.541 | X12: 1676838.2 | Y12: 2012205.8 | Z12: на ринку РДН | AA12: 5 | AB12: 14934.11 | AC12: 74670.55 | AD12: 89604.66
A13: на ринку ВДР | B13: 0 | C13: 0 | D13: 0 | E13: 0 | F13: на ринку ВДР | G13: 45.3 | H13: 10143.8 | I13: 459514.16 | J13: 551416.99 | K13: на ринку ВДР | L13: 64.5 | M13: 11213.333 | N13: 723259.97 | O13: 867911.96 | P13: на ринку ВДР | Q13: 38.5 | R13: 11498.006 | S13: 442673.25 | T13: 531207.9 | U13: на ринку ВДР | V13: 67.1 | W13: 12707.657 | X13: 852683.8 | Y13: 1023220.6 | Z13: на ринку ВДР | AA13: 230.9 | AB13: 13985.984 | AC13: 3229363.7 | AD13: 3875236.5
A14: електроенергія для врегулювання небалансів (КНЕСС) | B14: 63.495 | C14: 6629.365 | D14: 420931.53 | E14: 505117.84 | F14: електроенергія для врегулювання небалансів (КНЕСС) | G14: 96.365 | H14: 8848.5211 | I14: 852687.74 | J14: 1023225.3 | K14: електроенергія для врегулювання небалансів (КНЕСС) | L14: 55.725 | M14: 4458.1938 | N14: 248432.85 | O14: 298119.42 | P14: електроенергія для врегулювання небалансів (КНЕСС) | Q14: 81.505 | R14: 6560.1968 | S14: 534688.84 | T14: 641626.61 | U14: електроенергія для врегулювання небалансів (КНЕСС) | V14: 55.74 | W14: 7583.4073 | X14: 422699.12 | Y14: 507238.94 | Z14: електроенергія для врегулювання небалансів (КНЕСС) | AA14: 45.59 | AB14: 9213.6683 | AC14: 420051.14 | AD14: 504061.37
A15: САЛЬДО (продаж- купівля): | B15: -54 | C15: 1445.3106 | D15: -188168.94 | E15: -225802.73 | F15: САЛЬДО (продаж- купівля): | G15: -50.085 | H15: 5423.5518 | I15: 689757.57 | J15: 827709.08 | K15: САЛЬДО (продаж- купівля): | L15: -46.815 | M15: 6563.786 | N15: 1262836.3 | O15: 1515403.6 | P15: САЛЬДО (продаж- купівля): | Q15: -51.18 | R15: 5085.7732 | S15: 797786.81 | T15: 957344.17 | U15: САЛЬДО (продаж- купівля): | V15: -58.11 | W15: 4945.4477 | X15: 843212.45 | Y15: 1011854.9 | Z15: САЛЬДО (продаж- купівля): | AA15: -47.535 | AB15: 6167.4572 | AC15: 1400364.2 | AD15: 1680437
A17: ЗВІТ з купівлі-продажу електроенергії УЗЕ ТОВ ”ОЛЕКСАНДРІЙСЬКА БЕСС”- 15,33776 МВт*год на ринках електроенергії РДН/ВДР та у балансуючій групі КНЕСС у вересні 2025 року | F17: ЗВІТ з купівлі-продажу електроенергії УЗЕ ТОВ ”ОЛЕКСАНДРІЙСЬКА БЕСС”- 15,33776 МВт*год на ринках електроенергії РДН/ВДР та у балансуючій групі КНЕСС у жовтні 2025 року | K17: ЗВІТ з купівлі-продажу електроенергії УЗЕ ТОВ ”ОЛЕКСАНДРІЙСЬКА БЕСС”- 15,33776 МВт*год на ринках електроенергії РДН/ВДР та у балансуючій групі КНЕСС у листопаді 2025 року | P17: ЗВІТ з купівлі-продажу електроенергії УЗЕ ТОВ ”ОЛЕКСАНДРІЙСЬКА БЕСС”- 15,33776 МВт*год на ринках електроенергії РДН/ВДР та у балансуючій групі КНЕСС у грудні 2025 року | U17: ЗВІТ з купівлі-продажу електроенергії УЗЕ ТОВ ”ОЛЕКСАНДРІЙСЬКА БЕСС”- 15,33776 МВт*год на ринках електроенергії РДН/ВДР та у балансуючій групі КНЕСС у січні 2026 року | Z17: ЗВІТ з купівлі-продажу електроенергії УЗЕ ТОВ ”ОЛЕКСАНДРІЙСЬКА БЕСС”- 15,33776 МВт*год на ринках електроенергії РДН/ВДР та у балансуючій групі КНЕСС у лютому 2026 року
A19: ОПЕРАЦІЯ | B19: Обсяг, МВт*год | C19: Середньозважена ціна, грн | D19: Вартість без ПДВ, грн | E19: Вартість з ПДВ, грн | F19: ОПЕРАЦІЯ | G19: Обсяг, МВт*год | H19: Середньозважена ціна, грн | I19: Вартість без ПДВ, грн | J19: Вартість з ПДВ, грн | K19: ОПЕРАЦІЯ | L19: Обсяг, МВт*год | M19: Середньозважена ціна, грн | N19: Вартість без ПДВ, грн | O19: Вартість з ПДВ, грн | P19: ОПЕРАЦІЯ | Q19: Обсяг, МВт*год | R19: Середньозважена ціна, грн | S19: Вартість без ПДВ, грн | T19: Вартість з ПДВ, грн | U19: ОПЕРАЦІЯ | V19: Обсяг, МВт*год | W19: Середньозважена ціна, грн | X19: Вартість без ПДВ, грн | Y19: Вартість з ПДВ, грн | Z19: ОПЕРАЦІЯ | AA19: Обсяг, МВт*год | AB19: Середньозважена ціна, грн | AC19: Вартість без ПДВ, грн | AD19: Вартість з ПДВ, грн
A20: Купівля електроенергії: | B20: 295.424 | C20: 5002.8382 | D20: 1477958.5 | E20: 1773550.2 | F20: Купівля електроенергії: | G20: 289.092 | H20: 4665.8598 | I20: 1348862.8 | J20: 1618635.3 | K20: Купівля електроенергії: | L20: 361.672 | M20: 4245.7609 | N20: 1535572.8 | O20: 1842687.4 | P20: Купівля електроенергії: | Q20: 353.996 | R20: 5056.0548 | S20: 1789823.2 | T20: 2147787.8 | U20: Купівля електроенергії: | V20: 423.416 | W20: 6727.2913 | X20: 2848442.8 | Y20: 3418131.3 | Z20: Купівля електроенергії: | AA20: 422.796 | AB20: 6981.6525 | AC20: 2951814.7 | AD20: 3542177.7
A21: у т.ч. | F21: у т.ч. | K21: у т.ч. | P21: у т.ч. | U21: у т.ч. | Z21: у т.ч.
A22: постачання активної електроенергії (КНЕСС) | B22: 24.096 | C22: 6413.1897 | D22: 154532.22 | E22: 185438.66 | F22: постачання активної електроенергії (КНЕСС) | G22: 0 | H22: 0 | I22: 0 | J22: 0 | K22: постачання активної електроенергії (КНЕСС) | L22: 0 | M22: 0 | N22: 0 | O22: 0 | P22: постачання активної електроенергії (КНЕСС) | Q22: 0 | R22: 0 | S22: 0 | T22: 0 | U22: постачання активної електроенергії (КНЕСС) | V22: 0 | W22: 0 | X22: 0 | Y22: 0 | Z22: постачання активної електроенергії (КНЕСС) | AA22: 0 | AB22: 0 | AC22: 0 | AD22: 0
A23: на ринку РДН | B23: 0 | C23: 0 | D23: 0 | E23: 0 | F23: на ринку РДН | G23: 0 | H23: 0 | I23: 0 | J23: 0 | K23: на ринку РДН | L23: 8.6 | M23: 6666.9884 | N23: 57336.1 | O23: 68803.32 | P23: на ринку РДН | Q23: 130.2 | R23: 3471.1336 | S23: 451941.6 | T23: 542329.92 | U23: на ринку РДН | V23: 207.2 | W23: 5318.0753 | X23: 1101905.2 | Y23: 1322286.2 | Z23: на ринку РДН | AA23: 0 | AB23: 0 | AC23: 0 | AD23: 0
A24: на ринку ВДР | B24: 0 | C24: 0 | D24: 0 | E24: 0 | F24: на ринку ВДР | G24: 92 | H24: 2086.6125 | I24: 191968.35 | J24: 230362.02 | K24: на ринку ВДР | L24: 239.9 | M24: 2048.6764 | N24: 491477.47 | O24: 589772.96 | P24: на ринку ВДР | Q24: 51.1 | R24: 3741.672 | S24: 191199.44 | T24: 229439.33 | U24: на ринку ВДР | V24: 93.6 | W24: 6052.35 | X24: 566499.96 | Y24: 679799.95 | Z24: на ринку ВДР | AA24: 321.1 | AB24: 5631.731 | AC24: 1808348.8 | AD24: 2170018.6
A25: електроенергія для врегулювання небалансів (КНЕСС) | B25: 271.328 | C25: 4877.5882 | D25: 1323426.2 | E25: 1588111.5 | F25: електроенергія для врегулювання небалансів (КНЕСС) | G25: 197.092 | H25: 5869.8192 | I25: 1156894.4 | J25: 1388273.3 | K25: електроенергія для врегулювання небалансів (КНЕСС) | L25: 113.172 | M25: 8719.1112 | N25: 986759.25 | O25: 1184111.1 | P25: електроенергія для врегулювання небалансів (КНЕСС) | Q25: 172.696 | R25: 6639.8883 | S25: 1146682.1 | T25: 1376018.6 | U25: електроенергія для врегулювання небалансів (КНЕСС) | V25: 122.616 | W25: 9623.8468 | X25: 1180037.6 | Y25: 1416045.1 | Z25: електроенергія для врегулювання небалансів (КНЕСС) | AA25: 101.696 | AB25: 11243.962 | AC25: 1143465.9 | AD25: 1372159.1
A26: Продаж електроенергії | B26: 231.072 | C26: 6382.7611 | D26: 1474877.4 | E26: 1769852.9 | F26: Продаж електроенергії | G26: 224.996 | H26: 10656.498 | I26: 2397669.5 | J26: 2877203.4 | K26: Продаж електроенергії | L26: 298.984 | M26: 11352.033 | N26: 3394076.2 | O26: 4072891.4 | P26: Продаж електроенергії | Q26: 287.58 | R26: 10600.983 | S26: 3048630.7 | T26: 3658356.8 | U26: Продаж електроенергії | V26: 346.456 | W26: 11877.21 | X26: 4114930.5 | Y26: 4937916.6 | Z26: Продаж електроенергії | AA26: 362.124 | AB26: 13247.665 | AC26: 4797297.5 | AD26: 5756757
A27: у т.ч. | F27: у т.ч. | K27: у т.ч. | P27: у т.ч. | U27: у т.ч. | Z27: у т.ч.
A28: на ринку РДН | B28: 0 | C28: 0 | D28: 0 | E28: 0 | F28: на ринку РДН | G28: 43.2 | H28: 14834.848 | I28: 640865.43 | J28: 769038.52 | K28: на ринку РДН | L28: 147.3 | M28: 14438.575 | N28: 2126802.1 | O28: 2552162.6 | P28: на ринку РДН | Q28: 130.5 | R28: 13186.202 | S28: 1720799.3 | T28: 2064959.2 | U28: на ринку РДН | V28: 184.3 | W28: 13124.012 | X28: 2418755.4 | Y28: 2902506.5 | Z28: на ринку РДН | AA28: 7.4 | AB28: 14910.961 | AC28: 110341.11 | AD28: 132409.33
A29: на ринку ВДР | B29: 0 | C29: 0 | D29: 0 | E29: 0 | F29: на ринку ВДР | G29: 52.8 | H29: 10711.785 | I29: 565582.23 | J29: 678698.68 | K29: на ринку ВДР | L29: 88.3 | M29: 10928.729 | N29: 965006.8 | O29: 1158008.2 | P29: на ринку ВДР | Q29: 52.3 | R29: 11542.37 | S29: 603665.96 | T29: 724399.15 | U29: на ринку ВДР | V29: 89.9 | W29: 12480.049 | X29: 1121956.4 | Y29: 1346347.7 | Z29: на ринку ВДР | AA29: 301.2 | AB29: 13886.663 | AC29: 4182662.8 | AD29: 5019195.3
A30: електроенергія для врегулювання небалансів (КНЕСС) | B30: 231.072 | C30: 6382.7611 | D30: 1474877.4 | E30: 1769852.9 | F30: електроенергія для врегулювання небалансів (КНЕСС) | G30: 128.996 | H30: 9234.5641 | I30: 1191221.8 | J30: 1429466.2 | K30: електроенергія для врегулювання небалансів (КНЕСС) | L30: 63.384 | M30: 4768.8256 | N30: 302267.24 | O30: 362720.69 | P30: електроенергія для врегулювання небалансів (КНЕСС) | Q30: 104.78 | R30: 6911.294 | S30: 724165.38 | T30: 868998.46 | U30: електроенергія для врегулювання небалансів (КНЕСС) | V30: 72.256 | W30: 7947.0039 | X30: 574218.71 | Y30: 689062.45 | Z30: електроенергія для врегулювання небалансів (КНЕСС) | AA30: 53.524 | AB30: 9421.8222 | AC30: 504293.61 | AD30: 605152.33
A31: САЛЬДО (продаж- купівля): | B31: -64.352 | C31: 1379.9229 | D31: -3081.0925 | E31: -3697.3025 | F31: САЛЬДО (продаж- купівля): | G31: -64.096 | H31: 5990.6385 | I31: 1048806.7 | J31: 1258568.1 | K31: САЛЬДО (продаж- купівля): | L31: -62.688 | M31: 7106.2719 | N31: 1858503.3 | O31: 2230204 | P31: САЛЬДО (продаж- купівля): | Q31: -66.416 | R31: 5544.9281 | S31: 1258807.5 | T31: 1510569 | U31: САЛЬДО (продаж- купівля): | V31: -76.96 | W31: 5149.9183 | X31: 1266487.8 | Y31: 1519785.3 | Z31: САЛЬДО (продаж- купівля): | AA31: -60.672 | AB31: 6266.0127 | AC31: 1845482.8 | AD31: 2214579.3

Sheet КВІТЕНЬ_2026
A1: ЗВІТ з купівлі-продажу електроенергії УЗЕ ТОВ ”ЗНАМЕНСЬКА БЕСС”- 10,32180 МВт*год на ринках електроенергії РДН/ВДР та у балансуючій групі КНЕСС у квітні 2026 року
A3: ОПЕРАЦІЯ | B3: Обсяг, МВт*год | C3: Середньозважена ціна, грн/МВт*год | D3: Вартість без ПДВ, грн | E3: Вартість з ПДВ, грн
A4: Купівля електроенергії: | B4: =SUM(B6:B10) -> 300.1 | C4: =IF(ISERROR(D4/B4),0,D4/B4) -> 3999.0003 | D4: =SUM(D6:D10) -> 1200100 | E4: =SUM(E6:E10) -> 1440120
A5: у т.ч.
A6: постачання активної електроенергії (КНЕСС) | D6: =B6*C6 -> 0 | E6: =ROUND((D6*20%),2)+D6 -> 0
A7: на ринку РДН | B7: 0 | C7: 0 | D7: =B7*C7 -> 0 | E7: =ROUND((ROUND((D7*20%),2)+D7),2) -> 0
A8: на ринку ВДР | B8: 100.1 | C8: 1000 | D8: =B8*C8 -> 100100 | E8: =ROUND((ROUND((D8*20%),2)+D8),2) -> 120120
A9: купівля балансуючої електроенергії (НЕК "УКРЕНЕРГО") | B9: 100 | C9: 10000 | D9: =B9*C9 -> 1000000 | E9: =ROUND((ROUND((D9*20%),2)+D9),2) -> 1200000
A10: електроенергія для врегулювання небалансів (КНЕСС) | B10: 100 | C10: 1000 | D10: =B10*C10 -> 100000 | E10: =ROUND((ROUND((D10*20%),2)+D10),2) -> 120000
A11: Продаж електроенергії | B11: =SUM(B13:B16) -> 300 | C11: =IF(ISERROR(D11/B11),0,D11/B11) -> 100 | D11: =SUM(D13:D16) -> 30000 | E11: =SUM(E13:E16) -> 36000
A12: у т.ч.
A13: на ринку РДН | B13: 100 | C13: 100 | D13: =B13*C13 -> 10000 | E13: =ROUND((ROUND((D13*20%),2)+D13),2) -> 12000
A14: на ринку ВДР | B14: 100 | C14: 100 | D14: =B14*C14 -> 10000 | E14: =ROUND((ROUND((D14*20%),2)+D14),2) -> 12000
A15: продаж балансуючої електроенергії (НЕК "УКРЕНЕРГО") | D15: =B15*C15 -> 0 | E15: =ROUND((ROUND((D15*20%),2)+D15),2) -> 0
A16: електроенергія для врегулювання небалансів (КНЕСС) | B16: 100 | C16: 100 | D16: =B16*C16 -> 10000 | E16: =ROUND((ROUND((D16*20%),2)+D16),2) -> 12000
A17: САЛЬДО (продаж- купівля): | B17: =B11-B4 -> -0.1 | C17: =C11-C4 -> -3899.0003 | D17: =D11-D4 -> -1170100 | E17: =E11-E4 -> -1404120
A19: ЗВІТ з купівлі-продажу електроенергії УЗЕ ТОВ ”ОЛЕКСАНДРІЙСЬКА БЕСС”- 15,33776 МВт*год на ринках електроенергії РДН/ВДР та у балансуючій групі КНЕСС у квітні 2026 року
A21: ОПЕРАЦІЯ | B21: Обсяг, МВт*год | C21: Середньозважена ціна, грн/МВт*год | D21: Вартість без ПДВ, грн | E21: Вартість з ПДВ, грн
A22: Купівля електроенергії: | B22: =SUM(B24:B28) -> 311.014 | C22: =IF(ISERROR(D22/B22),0,D22/B22) -> 100 | D22: =SUM(D24:D28) -> 31101.4 | E22: =SUM(E24:E28) -> 37321.68
A23: у т.ч.
A24: постачання активної електроенергії (КНЕСС) | B24: 0 | C24: 0 | D24: =B24*C24 -> 0 | E24: =ROUND((D24*20%),2)+D24 -> 0
A25: на ринку РДН | B25: 0 | C25: 0 | D25: =B25*C25 -> 0 | E25: =ROUND((ROUND((D25*20%),2)+D25),2) -> 0
A26: на ринку ВДР | B26: 100 | C26: 100 | D26: =B26*C26 -> 10000 | E26: =ROUND((ROUND((D26*20%),2)+D26),2) -> 12000
A27: купівля балансуючої електроенергії (НЕК "УКРЕНЕРГО") | B27: 100 | C27: 100 | D27: =B27*C27 -> 10000 | E27: =ROUND((ROUND((D27*20%),2)+D27),2) -> 12000
A28: електроенергія для врегулювання небалансів (КНЕСС) | B28: 111.014 | C28: 100 | D28: =B28*C28 -> 11101.4 | E28: =ROUND((ROUND((D28*20%),2)+D28),2) -> 13321.68
A29: Продаж електроенергії | B29: =SUM(B31:B34) -> 300 | C29: =IF(ISERROR(D29/B29),0,D29/B29) -> 700 | D29: =SUM(D31:D34) -> 210000 | E29: =SUM(E31:E34) -> 252000
A30: у т.ч.
A31: на ринку РДН | B31: 100 | C31: 100 | D31: =B31*C31 -> 10000 | E31: =ROUND((ROUND((D31*20%),2)+D31),2) -> 12000
A32: на ринку ВДР | B32: 100 | C32: 1000 | D32: =B32*C32 -> 100000 | E32: =ROUND((ROUND((D32*20%),2)+D32),2) -> 120000
A33: продаж балансуючої електроенергії (НЕК "УКРЕНЕРГО") | D33: =B33*C33 -> 0 | E33: =ROUND((ROUND((D33*20%),2)+D33),2) -> 0
A34: електроенергія для врегулювання небалансів (КНЕСС) | B34: 100 | C34: 1000 | D34: =B34*C34 -> 100000 | E34: =ROUND((ROUND((D34*20%),2)+D34),2) -> 120000
A35: САЛЬДО (продаж- купівля): | B35: =B29-B22 -> -11.014 | C35: =C29-C22 -> 600 | D35: =D29-D22 -> 178898.6 | E35: =E29-E22 -> 214678.32

Sheet КВІТЕНЬ_2026 (АРБІТРАЖ)
A1: ЗВІТ з купівлі-продажу електроенергії УЗЕ ТОВ ”ЗНАМЕНСЬКА БЕСС”- 10,32180 МВт*год на ринках електроенергії РДН/ВДР та у балансуючій групі КНЕСС у квітні 2026 року
A3: ОПЕРАЦІЯ | B3: Обсяг, МВт*год | C3: Середньозважена ціна, грн/МВт*год | D3: Вартість без ПДВ, грн | E3: Вартість з ПДВ, грн | G3: Для себя
A4: Купівля електроенергії: | B4: =SUM(B6:B8) -> 219.1 | C4: =IF(ISERROR(D4/B4),0,D4/B4) -> 1286.1125 | D4: =SUM(D6:D8) -> 281787.24 | E4: =SUM(E6:E8) -> 338144.69 | G4: =SUM(G6:G8) -> 219.1
A5: у т.ч.
A6: постачання активної електроенергії (КНЕСС) | D6: =B6*C6 -> 0 | E6: =ROUND((D6*20%),2)+D6 -> 0
A7: на ринку РДН | B7: 0 | C7: 0 | D7: =B7*C7 -> 0 | E7: =ROUND((ROUND((D7*20%),2)+D7),2) -> 0 | G7: =B7 -> 0
A8: на ринку ВДР | B8: 219.1 | C8: 1286.1125 | D8: =B8*C8 -> 281787.24 | E8: =ROUND((ROUND((D8*20%),2)+D8),2) -> 338144.69 | G8: =B8 -> 219.1
A9: Продаж електроенергії | B9: =SUM(B11:B13) -> 313.8 | C9: =IF(ISERROR(D9/B9),0,D9/B9) -> 10577.362 | D9: =SUM(D11:D13) -> 3319176.1 | E9: =SUM(E11:E13) -> 3983011.3 | G9: =SUM(G11:G13) -> 313.8
A10: у т.ч.
A11: на ринку РДН | B11: 178 | C11: 12541.377 | D11: =B11*C11 -> 2232365.1 | E11: =ROUND((ROUND((D11*20%),2)+D11),2) -> 2678838.1 | G11: =B11 -> 178
A12: на ринку ВДР | B12: 135.8 | C12: 8003.0267 | D12: =B12*C12 -> 1086811 | E12: =ROUND((ROUND((D12*20%),2)+D12),2) -> 1304173.2 | G12: =B12 -> 135.8
A13: продаж балансуючої електроенергії (НЕК "УКРЕНЕРГО") | D13: =B13*C13 -> 0 | E13: =ROUND((ROUND((D13*20%),2)+D13),2) -> 0
A14: САЛЬДО (продаж- купівля): | B14: =B9-B4 -> 94.7 | C14: =C9-C4 -> 9291.2493 | D14: =D9-D4 -> 3037388.9 | E14: =E9-E4 -> 3644866.7 | G14: =G9-G4 -> 94.7
A16: ЗВІТ з купівлі-продажу електроенергії УЗЕ ТОВ ”ОЛЕКСАНДРІЙСЬКА БЕСС”- 15,33776 МВт*год на ринках електроенергії РДН/ВДР та у балансуючій групі КНЕСС у квітні 2026 року
A18: ОПЕРАЦІЯ | B18: Обсяг, МВт*год | C18: Середньозважена ціна, грн/МВт*год | D18: Вартість без ПДВ, грн | E18: Вартість з ПДВ, грн
A19: Купівля електроенергії: | B19: =SUM(B21:B23) -> 296.2 | C19: =IF(ISERROR(D19/B19),0,D19/B19) -> 1197.6595 | D19: =SUM(D21:D23) -> 354746.74 | E19: =SUM(E21:E23) -> 425696.09 | G19: =SUM(G21:G23) -> 296.2
A20: у т.ч.
A21: постачання активної електроенергії (КНЕСС) | B21: 0 | C21: 0 | D21: =B21*C21 -> 0 | E21: =ROUND((D21*20%),2)+D21 -> 0
A22: на ринку РДН | B22: 0 | C22: 0 | D22: =B22*C22 -> 0 | E22: =ROUND((ROUND((D22*20%),2)+D22),2) -> 0 | G22: =B22 -> 0
A23: на ринку ВДР | B23: 296.2 | C23: 1197.6595 | D23: =B23*C23 -> 354746.74 | E23: =ROUND((ROUND((D23*20%),2)+D23),2) -> 425696.09 | G23: =B23 -> 296.2
A24: Продаж електроенергії | B24: =SUM(B26:B28) -> 382.6 | C24: =IF(ISERROR(D24/B24),0,D24/B24) -> 10567.149 | D24: =SUM(D26:D28) -> 4042991.4 | E24: =SUM(E26:E28) -> 4851589.7 | G24: =SUM(G26:G28) -> 382.6
A25: у т.ч.
A26: на ринку РДН | B26: 202.4 | C26: 12603.682 | D26: =B26*C26 -> 2550985.3 | E26: =ROUND((ROUND((D26*20%),2)+D26),2) -> 3061182.3 | G26: =B26 -> 202.4
A27: на ринку ВДР | B27: 180.2 | C27: 8279.7233 | D27: =B27*C27 -> 1492006.1 | E27: =ROUND((ROUND((D27*20%),2)+D27),2) -> 1790407.4 | G27: =B27 -> 180.2
A28: продаж балансуючої електроенергії (НЕК "УКРЕНЕРГО") | D28: =B28*C28 -> 0 | E28: =ROUND((ROUND((D28*20%),2)+D28),2) -> 0
A29: САЛЬДО (продаж- купівля): | B29: =B24-B19 -> 86.4 | C29: =C24-C19 -> 9369.49 | D29: =D24-D19 -> 3688244.7 | E29: =E24-E19 -> 4425893.6 | G29: =G24-G19 -> 86.4

Sheet ТРАВЕНЬ_2026 (АРБІТРАЖ)
A1: ЗВІТ з купівлі-продажу електроенергії УЗЕ ТОВ ”ЗНАМЕНСЬКА БЕСС”- 10,32180 МВт*год на ринках електроенергії РДН/ВДР та у балансуючій групі КНЕСС у травні 2026 року (01-04/05/2026)
A3: ОПЕРАЦІЯ | B3: Обсяг, МВт*год | C3: Середньозважена ціна, грн/МВт*год | D3: Вартість без ПДВ, грн | E3: Вартість з ПДВ, грн | G3: Для себя
A4: Купівля електроенергії: | B4: =SUM(B6:B8) -> 41.1 | C4: =IF(ISERROR(D4/B4),0,D4/B4) -> 1377.1192 | D4: =SUM(D6:D8) -> 56599.6 | E4: =SUM(E6:E8) -> 67919.52 | G4: =SUM(G6:G8) -> 41.1
A5: у т.ч.
A6: постачання активної електроенергії (КНЕСС) | D6: =B6*C6 -> 0 | E6: =ROUND((D6*20%),2)+D6 -> 0
A7: на ринку РДН | B7: 0 | C7: 0 | D7: =B7*C7 -> 0 | E7: =ROUND((ROUND((D7*20%),2)+D7),2) -> 0 | G7: =B7 -> 0
A8: на ринку ВДР | B8: 41.1 | C8: =ROUND(F8/B8,10) -> 1377.1192 | D8: =B8*C8 -> 56599.6 | E8: =ROUND((ROUND((D8*20%),2)+D8),2) -> 67919.52 | F8: 56599.6 | G8: =B8 -> 41.1
A9: Продаж електроенергії | B9: =SUM(B11:B13) -> 46.6 | C9: =IF(ISERROR(D9/B9),0,D9/B9) -> 9528.277 | D9: =SUM(D11:D13) -> 444017.71 | E9: =SUM(E11:E13) -> 532821.25 | G9: =SUM(G11:G13) -> 46.6
A10: у т.ч.
A11: на ринку РДН | B11: 20.3 | C11: =ROUND(F11/B11,10) -> 11371.631 | D11: =B11*C11 -> 230844.1 | E11: =ROUND((ROUND((D11*20%),2)+D11),2) -> 277012.92 | F11: 230844.1 | G11: =B11 -> 20.3
A12: на ринку ВДР | B12: 26.3 | C12: =ROUND(F12/B12,10) -> 8105.4605 | D12: =B12*C12 -> 213173.61 | E12: =ROUND((ROUND((D12*20%),2)+D12),2) -> 255808.33 | F12: 213173.61 | G12: =B12 -> 26.3
A13: продаж балансуючої електроенергії (НЕК "УКРЕНЕРГО") | D13: =B13*C13 -> 0 | E13: =ROUND((ROUND((D13*20%),2)+D13),2) -> 0
A14: САЛЬДО (продаж- купівля): | B14: =B9-B4 -> 5.5 | C14: =C9-C4 -> 8151.1578 | D14: =D9-D4 -> 387418.11 | E14: =E9-E4 -> 464901.73 | G14: =G9-G4 -> 5.5
A16: ЗВІТ з купівлі-продажу електроенергії УЗЕ ТОВ ”ОЛЕКСАНДРІЙСЬКА БЕСС”- 15,33776 МВт*год на ринках електроенергії РДН/ВДР та у балансуючій групі КНЕСС у травні 2026 року (01-04/05/2026)
A18: ОПЕРАЦІЯ | B18: Обсяг, МВт*год | C18: Середньозважена ціна, грн/МВт*год | D18: Вартість без ПДВ, грн | E18: Вартість з ПДВ, грн
A19: Купівля електроенергії: | B19: =SUM(B21:B23) -> 52.3 | C19: =IF(ISERROR(D19/B19),0,D19/B19) -> 977.31166 | D19: =SUM(D21:D23) -> 51113.4 | E19: =SUM(E21:E23) -> 61336.08 | G19: =SUM(G21:G23) -> 52.3
A20: у т.ч.
A21: постачання активної електроенергії (КНЕСС) | B21: 0 | C21: 0 | D21: =B21*C21 -> 0 | E21: =ROUND((D21*20%),2)+D21 -> 0
A22: на ринку РДН | B22: 0 | C22: 0 | D22: =B22*C22 -> 0 | E22: =ROUND((ROUND((D22*20%),2)+D22),2) -> 0 | G22: =B22 -> 0
A23: на ринку ВДР | B23: 52.3 | C23: =ROUND(F23/B23,10) -> 977.31166 | D23: =B23*C23 -> 51113.4 | E23: =ROUND((ROUND((D23*20%),2)+D23),2) -> 61336.08 | F23: 51113.4 | G23: =B23 -> 52.3
A24: Продаж електроенергії | B24: =SUM(B26:B28) -> 52.9 | C24: =IF(ISERROR(D24/B24),0,D24/B24) -> 9019.0692 | D24: =SUM(D26:D28) -> 477108.76 | E24: =SUM(E26:E28) -> 572530.51 | G24: =SUM(G26:G28) -> 52.9
A25: у т.ч.
A26: на ринку РДН | B26: 26 | C26: =ROUND(F26/B26,10) -> 11053.608 | D26: =B26*C26 -> 287393.8 | E26: =ROUND((ROUND((D26*20%),2)+D26),2) -> 344872.56 | F26: 287393.8 | G26: =B26 -> 26
A27: на ринку ВДР | B27: 26.9 | C27: =ROUND(F27/B27,10) -> 7052.6007 | D27: =B27*C27 -> 189714.96 | E27: =ROUND((ROUND((D27*20%),2)+D27),2) -> 227657.95 | F27: 189714.96 | G27: =B27 -> 26.9
A28: продаж балансуючої електроенергії (НЕК "УКРЕНЕРГО") | D28: =B28*C28 -> 0 | E28: =ROUND((ROUND((D28*20%),2)+D28),2) -> 0
A29: САЛЬДО (продаж- купівля): | B29: =B24-B19 -> 0.6 | C29: =C24-C19 -> 8041.7575 | D29: =D24-D19 -> 425995.36 | E29: =E24-E19 -> 511194.43 | G29: =G24-G19 -> 0.6

Sheet ОБСЯГИ
A2: УЗЕ ТОВ ”ЗНАМЕНСЬКА БЕСС”- 10,32180 МВт*год | B2: 45901 | C2: 45931 | D2: 45962 | E2: 45992 | F2: 46023 | G2: 46054 | H2: 46082
A3: ОПЕРАЦІЯ | B3: Обсяг, МВт*год | C3: Обсяг, МВт*год | D3: Обсяг, МВт*год | E3: Обсяг, МВт*год | F3: Обсяг, МВт*год | G3: Обсяг, МВт*год | H3: Обсяг, МВт*год
A4: Купівля електроенергії: | B4: 117.495 | C4: 221.75 | D4: 271.14 | E4: =SUM(E6:E10) -> 260.585 | F4: =SUM(F6:F10) -> 308.85 | G4: =SUM(G6:G10) -> 329.025 | H4: =SUM(H6:H10) -> 440.15833
A5: у т.ч.
A6: постачання активної електроенергії (КНЕСС) | B6: 37.26 | C6: 0 | D6: 0 | E6: 0 | F6: 0 | G6: 0 | H6: 0
A7: на ринку РДН | B7: 0 | C7: 0 | D7: 7.8 | E7: 91.7 | F7: 143.8 | G7: 0 | H7: 13.8
A8: на ринку ВДР | B8: 0 | C8: 68 | D8: 170.5 | E8: 35.3 | F8: 65.8 | G8: 245.2 | H8: 261.4
A9: купівля балансуючої електроенергії (НЕК "УКРЕНЕРГО") | H9: 70.833335
A10: електроенергія для врегулювання небалансів (КНЕСС) | B10: 80.235 | C10: 153.75 | D10: 92.84 | E10: 133.585 | F10: 99.25 | G10: 83.825 | H10: 94.124999
A11: Продаж електроенергії | B11: 63.495 | C11: 171.665 | D11: 224.325 | E11: =SUM(E13:E16) -> 209.405 | F11: =SUM(F13:F16) -> 250.74 | G11: =SUM(G13:G16) -> 281.49 | H11: =SUM(H13:H16) -> 371.72833
A12: у т.ч.
A13: на ринку РДН | B13: 0 | C13: 30 | D13: 104.1 | E13: 89.4 | F13: 127.9 | G13: 5 | H13: 137.9
A14: на ринку ВДР | B14: 0 | C14: 45.3 | D14: 64.5 | E14: 38.5 | F14: 67.1 | G14: 230.9 | H14: 175.2
A15: продаж балансуючої електроенергії (НЕК "УКРЕНЕРГО") | H15: 0
A16: електроенергія для врегулювання небалансів (КНЕСС) | B16: 63.495 | C16: 96.365 | D16: 55.725 | E16: 81.505 | F16: 55.74 | G16: 45.59 | H16: 58.628334
A17: САЛЬДО (продаж- купівля): | B17: -54 | C17: -50.085 | D17: -46.815 | E17: =E11-E4 -> -51.18 | F17: =F11-F4 -> -58.11 | G17: =G11-G4 -> -47.535 | H17: =H11-H4 -> -68.43
A20: УЗЕ ТОВ ”ОЛЕКСАНДРІЙСЬКА БЕСС”- 15,33776 МВт*год | B20: 45901 | C20: 45931 | D20: 45962 | E20: 45992 | F20: 46023 | G20: 46054 | H20: 46082
A21: ОПЕРАЦІЯ | B21: Обсяг, МВт*год | C21: Обсяг, МВт*год | D21: Обсяг, МВт*год | E21: Обсяг, МВт*год | F21: Обсяг, МВт*год | G21: Обсяг, МВт*год | H21: Обсяг, МВт*год
A22: Купівля електроенергії: | B22: 295.424 | C22: 289.092 | D22: 361.672 | E22: =SUM(E24:E28) -> 353.996 | F22: =SUM(F24:F28) -> 423.416 | G22: =SUM(G24:G28) -> 422.796 | H22: =SUM(H24:H28) -> 560.28467
A23: у т.ч.
A24: постачання активної електроенергії (КНЕСС) | B24: 24.096 | C24: 0 | D24: 0 | E24: 0 | F24: 0 | G24: 0 | H24: 0
A25: на ринку РДН | B25: 0 | C25: 0 | D25: 8.6 | E25: 130.2 | F25: 207.2 | G25: 0 | H25: 19.8
A26: на ринку ВДР | B26: 0 | C26: 92 | D26: 239.9 | E26: 51.1 | F26: 93.6 | G26: 321.1 | H26: 341.1
A27: купівля балансуючої електроенергії (НЕК "УКРЕНЕРГО") | H27: 80.850001
A28: електроенергія для врегулювання небалансів (КНЕСС) | B28: 271.328 | C28: 197.092 | D28: 113.172 | E28: 172.696 | F28: 122.616 | G28: 101.696 | H28: 118.53467
A29: Продаж електроенергії | B29: 231.072 | C29: 224.996 | D29: 298.984 | E29: =SUM(E31:E34) -> 287.58 | F29: =SUM(F31:F34) -> 346.456 | G29: =SUM(G31:G34) -> 362.124 | H29: =SUM(H31:H34) -> 471.72467
A30: у т.ч.
A31: на ринку РДН | B31: 0 | C31: 43.2 | D31: 147.3 | E31: 130.5 | F31: 184.3 | G31: 7.4 | H31: 191.3
A32: на ринку ВДР | B32: 0 | C32: 52.8 | D32: 88.3 | E32: 52.3 | F32: 89.9 | G32: 301.2 | H32: 210.7
A33: продаж балансуючої електроенергії (НЕК "УКРЕНЕРГО") | H33: 0
A34: електроенергія для врегулювання небалансів (КНЕСС) | B34: 231.072 | C34: 128.996 | D34: 63.384 | E34: 104.78 | F34: 72.256 | G34: 53.524 | H34: 69.724667
A35: САЛЬДО (продаж- купівля): | B35: -64.352 | C35: -64.096 | D35: -62.688 | E35: =E29-E22 -> -66.416 | F35: =F29-F22 -> -76.96 | G35: =G29-G22 -> -60.672 | H35: =H29-H22 -> -88.56

Sheet ОБСЯГ_ВДР_РДН
A1: ЗВІТ з купівлі-продажу електроенергії УЗЕ ТОВ ”ЗНАМЕНСЬКА БЕСС”- 10,32180 МВт*год на ринках електроенергії РДН/ВДР у 2025, 2026 роках
B2: 45931 | C2: 45962 | D2: 45992 | E2: 46023 | F2: 46054 | G2: 46082 | H2: 46113 | I2: травень 2026 (4 дні)
A3: ОПЕРАЦІЯ | B3: Обсяг, МВт*год | C3: Обсяг, МВт*год | D3: Обсяг, МВт*год | E3: Обсяг, МВт*год | F3: Обсяг, МВт*год | G3: Обсяг, МВт*год | H3: Обсяг, МВт*год | I3: Обсяг, МВт*год
A4: Купівля електроенергії: | B4: =SUM(B6:B7) -> 68 | C4: =SUM(C6:C7) -> 178.3 | D4: =SUM(D6:D7) -> 127 | E4: =SUM(E6:E7) -> 209.6 | F4: =SUM(F6:F7) -> 245.2 | G4: =SUM(G6:G7) -> 275.2 | H4: =SUM(H6:H7) -> 219.1 | I4: =SUM(I6:I7) -> 41.1
A5: у т.ч.
A6: на ринку РДН | B6: 0 | C6: 7.8 | D6: 91.7 | E6: 143.8 | F6: 0 | G6: 13.8 | H6: 0 | I6: 0
A7: на ринку ВДР | B7: 68 | C7: 170.5 | D7: 35.3 | E7: 65.8 | F7: 245.2 | G7: 261.4 | H7: 219.1 | I7: 41.1
A8: Продаж електроенергії | B8: =SUM(B10:B11) -> 75.3 | C8: =SUM(C10:C11) -> 168.6 | D8: =SUM(D10:D11) -> 127.9 | E8: =SUM(E10:E11) -> 195 | F8: =SUM(F10:F11) -> 235.9 | G8: =SUM(G10:G11) -> 313.1 | H8: =SUM(H10:H11) -> 313.8 | I8: =SUM(I10:I11) -> 46.6
A9: у т.ч.
A10: на ринку РДН | B10: 30 | C10: 104.1 | D10: 89.4 | E10: 127.9 | F10: 5 | G10: 137.9 | H10: 178 | I10: 20.3
A11: на ринку ВДР | B11: 45.3 | C11: 64.5 | D11: 38.5 | E11: 67.1 | F11: 230.9 | G11: 175.2 | H11: 135.8 | I11: 26.3
A12: САЛЬДО (продаж- купівля): | B12: =B8-B4 -> 7.3 | C12: =C8-C4 -> -9.7 | D12: =D8-D4 -> 0.9 | E12: =E8-E4 -> -14.6 | F12: =F8-F4 -> -9.3 | G12: =G8-G4 -> 37.9 | H12: =H8-H4 -> 94.7 | I12: =I8-I4 -> 5.5
A14: ЗВІТ з купівлі-продажу електроенергії УЗЕ ТОВ ”ОЛЕКСАНДРІЙСЬКА БЕСС”- 15,33776 МВт*год на ринках електроенергії РДН/ВДР у 2025, 2026 роках
B15: 45931 | C15: 45962 | D15: 45992 | E15: 46023 | F15: 46054 | G15: 46082 | H15: 46113 | I15: травень 2026 (4 дні)
A16: ОПЕРАЦІЯ | B16: Обсяг, МВт*год | C16: Обсяг, МВт*год | D16: Обсяг, МВт*год | E16: Обсяг, МВт*год | F16: Обсяг, МВт*год | G16: Обсяг, МВт*год | H16: Обсяг, МВт*год | I16: Обсяг, МВт*год
A17: Купівля електроенергії: | B17: =SUM(B19:B20) -> 92 | C17: =SUM(C19:C20) -> 248.5 | D17: =SUM(D19:D20) -> 181.3 | E17: =SUM(E19:E20) -> 300.8 | F17: =SUM(F19:F20) -> 321.1 | G17: =SUM(G19:G20) -> 360.9 | H17: =SUM(H19:H20) -> 296.2 | I17: =SUM(I19:I20) -> 52.3
A18: у т.ч.
A19: на ринку РДН | B19: 0 | C19: 8.6 | D19: 130.2 | E19: 207.2 | F19: 0 | G19: 19.8 | H19: 0 | I19: 0
A20: на ринку ВДР | B20: 92 | C20: 239.9 | D20: 51.1 | E20: 93.6 | F20: 321.1 | G20: 341.1 | H20: 296.2 | I20: 52.3
A21: Продаж електроенергії | B21: =SUM(B23:B24) -> 96 | C21: =SUM(C23:C24) -> 235.6 | D21: =SUM(D23:D24) -> 182.8 | E21: =SUM(E23:E24) -> 274.2 | F21: =SUM(F23:F24) -> 308.6 | G21: =SUM(G23:G24) -> 402 | H21: =SUM(H23:H24) -> 382.6 | I21: =SUM(I23:I24) -> 52.9
A22: у т.ч.
A23: на ринку РДН | B23: 43.2 | C23: 147.3 | D23: 130.5 | E23: 184.3 | F23: 7.4 | G23: 191.3 | H23: 202.4 | I23: 26
A24: на ринку ВДР | B24: 52.8 | C24: 88.3 | D24: 52.3 | E24: 89.9 | F24: 301.2 | G24: 210.7 | H24: 180.2 | I24: 26.9
A25: САЛЬДО (продаж- купівля): | B25: =B21-B17 -> 4 | C25: =C21-C17 -> -12.9 | D25: =D21-D17 -> 1.5 | E25: =E21-E17 -> -26.6 | F25: =F21-F17 -> -12.5 | G25: =G21-G17 -> 41.1 | H25: =H21-H17 -> 86.4 | I25: =I21-I17 -> 0.6

Sheet ВАРТІСТЬ_ВДР_РДН
A1: ЗВІТ з купівлі-продажу електроенергії УЗЕ ТОВ ”ЗНАМЕНСЬКА БЕСС”- 10,32180 МВт*год на ринках електроенергії РДН/ВДР у 2025, 2026 роках
B2: 45931 | C2: 45962 | D2: 45992 | E2: 46023 | F2: 46054 | G2: 46082 | H2: 46113 | I2: травень 2026 (4 дні)
A3: ОПЕРАЦІЯ | B3: Вартість з ПДВ, грн | C3: Вартість з ПДВ, грн | D3: Вартість з ПДВ, грн | E3: Вартість з ПДВ, грн | F3: Вартість з ПДВ, грн | G3: Вартість з ПДВ, грн | H3: Вартість з ПДВ, грн | I3: Вартість з ПДВ, грн
A4: Купівля електроенергії: | B4: =SUM(B6:B7) -> 166910.03 | C4: =SUM(C6:C7) -> 479877.18 | D4: =SUM(D6:D7) -> 519333.22 | E4: =SUM(E6:E7) -> 1378215.6 | F4: =SUM(F6:F7) -> 1653548 | G4: =SUM(G6:G7) -> 1100918.8 | H4: =SUM(H6:H7) -> 338144.69 | I4: =SUM(I6:I7) -> 67919.52
A5: у т.ч.
A6: на ринку РДН | B6: 0 | C6: 62397.94 | D6: 373712.64 | E6: 912021.82 | F6: 0 | G6: 20286 | H6: 0 | I6: 0
A7: на ринку ВДР | B7: 166910.03 | C7: 417479.24 | D7: 145620.58 | E7: 466193.81 | F7: 1653548 | G7: 1080632.8 | H7: 338144.69 | I7: 67919.52
